Workbook

Sheet README
A1: Paramount Resources — Module 2: Five-Year Operating Model
A2: Asset-level production forecast driving revenue, netback, adjusted funds flow and free cash flow, 2026E–2030E.
A4: HOW THIS MODEL WORKS
A5: Structure | B5: Assumptions drive Production, which drives Revenue_Netback, which drives Cash_Flow. Summary reports outputs and runs sanity checks against company guidance.
A6: Scenario switch | B6: Assumptions!B4. Enter 1 for Bear, 2 for Base, 3 for Bull. Every price line re-reads automatically.
A7: Self-contained | B7: The price deck is duplicated here rather than linked to the Data Book, so the file runs standalone. If you change the deck in one file, change it in both.
A8: Units | B8: Volumes in Boe/d unless stated. Gas converted at 6 Mcf : 1 Boe. All dollars are Canadian millions unless stated.
A9: Colour | B9: Blue = hardcoded assumption you own. Black = formula. Green = cross-sheet link. Yellow = the levers that move the answer.
A11: THE THREE JUDGEMENTS THAT DRIVE THE ANSWER
A12: 1. Willesden Green ramp | B12: Grows from ~27.5 kBoe/d in Q2 2026 toward the company's stated ~50 kBoe/d plateau. Liquids-rich (~55%), so it carries the revenue.
A13: 2. Sinclair timing | B13: First gas Q4 2027, ramping through 2028. Firm egress of 335 MMcf/d caps it near 56 kBoe/d. Dry gas, so it adds volume far faster than it adds netback.
A14: 3. Kaybob decline | B14: Held at 19–20 kBoe/d to 2028 per company guidance, then declining as capital stays with the growth assets.
A16: RECONCILIATION TO GUIDANCE — read this before defending the model
A17: 2026E and 2027E | B17: Tuned to land inside company guidance. Summary tab checks this automatically.
A18: The 2027 exit rate | B18: The company guides to over 100,000 Boe/d exiting 2027 while guiding 2027 average volumes of only 60,000–65,000. Those reconcile only if the exit rate is a December spot rate rather than a Q4 average. This model assumes exactly that, and it is the single most important interpretive call in the file. State it out loud in any interview.
A19: The oil price deck | B19: WTI traded near US$86 in late August 2026, driven by US-Iran tension and Strait of Hormuz disruption, with futures in backwardation. The Base case therefore starts near spot and declines as the geopolitical risk premium unwinds toward mid-cycle. Bear assumes rapid de-escalation; Bull assumes sustained disruption. Do not model spot flat for five years — the forward curve does not.
A20: 2028E–2030E | B20: No company guidance exists. These are my assumptions and should be defended on Sinclair egress capacity and the Willesden Green plateau, not on management statements.
A22: Hypothetical case study. Not investment advice.

Sheet Assumptions
A1: Assumptions & Scenario Switch
A2: Yellow cells are the levers. Everything downstream is formula-driven off this sheet.
A4: SCENARIO (1 = Bear, 2 = Base, 3 = Bull) | B4: 2 | H4: Change this one cell to re-run the whole model.
A6: BEAR PRICE DECK
B7: 2026E | C7: 2027E | D7: 2028E | E7: 2029E | F7: 2030E | H7: Note
A8: WTI (US$/Bbl) | B8: 76 | C8: 62 | D8: 58 | E8: 58 | F8: 58
A9: AECO (C$/GJ) | B9: 1.9 | C9: 1.8 | D9: 1.9 | E9: 2 | F9: 2.1
A10: Diversification premium (C$/GJ) | B10: 0.7 | C10: 0.7 | D10: 0.7 | E10: 0.7 | F10: 0.7
A11: CAD/USD | B11: 1.38 | C11: 1.4 | D11: 1.42 | E11: 1.42 | F11: 1.42
A12: Condensate diff. to WTI (C$/Bbl) | B12: -2 | C12: -2 | D12: -2 | E12: -2 | F12: -2
A14: BASE PRICE DECK
B15: 2026E | C15: 2027E | D15: 2028E | E15: 2029E | F15: 2030E | H15: Note
A16: WTI (US$/Bbl) | B16: 80 | C16: 75 | D16: 72 | E16: 70 | F16: 70
A17: AECO (C$/GJ) | B17: 2.4 | C17: 2.9 | D17: 3.2 | E17: 3.3 | F17: 3.4
A18: Diversification premium (C$/GJ) | B18: 0.9 | C18: 0.9 | D18: 0.9 | E18: 0.9 | F18: 0.9
A19: CAD/USD | B19: 1.37 | C19: 1.36 | D19: 1.35 | E19: 1.35 | F19: 1.35
A20: Condensate diff. to WTI (C$/Bbl) | B20: 0 | C20: 0 | D20: 0 | E20: 0 | F20: 0
A22: BULL PRICE DECK
B23: 2026E | C23: 2027E | D23: 2028E | E23: 2029E | F23: 2030E | H23: Note
A24: WTI (US$/Bbl) | B24: 84 | C24: 95 | D24: 92 | E24: 90 | F24: 88
A25: AECO (C$/GJ) | B25: 3 | C25: 4 | D25: 4.5 | E25: 4.75 | F25: 5
A26: Diversification premium (C$/GJ) | B26: 1.1 | C26: 1.2 | D26: 1.2 | E26: 1.2 | F26: 1.2
A27: CAD/USD | B27: 1.35 | C27: 1.33 | D27: 1.32 | E27: 1.32 | F27: 1.32
A28: Condensate diff. to WTI (C$/Bbl) | B28: 2 | C28: 2 | D28: 2 | E28: 2 | F28: 2
A30: ACTIVE PRICE DECK — read by Revenue_Netback
B31: 2026E | C31: 2027E | D31: 2028E | E31: 2029E | F31: 2030E | H31: Note
A32: WTI (US$/Bbl) | B32: =IF($B$4=1,B8,IF($B$4=3,B24,B16)) -> 80 | C32: =IF($B$4=1,C8,IF($B$4=3,C24,C16)) -> 75 | D32: =IF($B$4=1,D8,IF($B$4=3,D24,D16)) -> 72 | E32: =IF($B$4=1,E8,IF($B$4=3,E24,E16)) -> 70 | F32: =IF($B$4=1,F8,IF($B$4=3,F24,F16)) -> 70
A33: AECO (C$/GJ) | B33: =IF($B$4=1,B9,IF($B$4=3,B25,B17)) -> 2.4 | C33: =IF($B$4=1,C9,IF($B$4=3,C25,C17)) -> 2.9 | D33: =IF($B$4=1,D9,IF($B$4=3,D25,D17)) -> 3.2 | E33: =IF($B$4=1,E9,IF($B$4=3,E25,E17)) -> 3.3 | F33: =IF($B$4=1,F9,IF($B$4=3,F25,F17)) -> 3.4
A34: Diversification premium (C$/GJ) | B34: =IF($B$4=1,B10,IF($B$4=3,B26,B18)) -> 0.9 | C34: =IF($B$4=1,C10,IF($B$4=3,C26,C18)) -> 0.9 | D34: =IF($B$4=1,D10,IF($B$4=3,D26,D18)) -> 0.9 | E34: =IF($B$4=1,E10,IF($B$4=3,E26,E18)) -> 0.9 | F34: =IF($B$4=1,F10,IF($B$4=3,F26,F18)) -> 0.9
A35: CAD/USD | B35: =IF($B$4=1,B11,IF($B$4=3,B27,B19)) -> 1.37 | C35: =IF($B$4=1,C11,IF($B$4=3,C27,C19)) -> 1.36 | D35: =IF($B$4=1,D11,IF($B$4=3,D27,D19)) -> 1.35 | E35: =IF($B$4=1,E11,IF($B$4=3,E27,E19)) -> 1.35 | F35: =IF($B$4=1,F11,IF($B$4=3,F27,F19)) -> 1.35
A36: Condensate diff. to WTI (C$/Bbl) | B36: =IF($B$4=1,B12,IF($B$4=3,B28,B20)) -> 0 | C36: =IF($B$4=1,C12,IF($B$4=3,C28,C20)) -> 0 | D36: =IF($B$4=1,D12,IF($B$4=3,D28,D20)) -> 0 | E36: =IF($B$4=1,E12,IF($B$4=3,E28,E20)) -> 0 | F36: =IF($B$4=1,F12,IF($B$4=3,F28,F20)) -> 0
A38: REALISED PRICE BUILD
B39: 2026E | C39: 2027E | D39: 2028E | E39: 2029E | F39: 2030E | H39: Note
A40: Realised natural gas (C$/Mcf) | B40: =(B33+B34)*1.055 -> 3.4815 | C40: =(C33+C34)*1.055 -> 4.009 | D40: =(D33+D34)*1.055 -> 4.3255 | E40: =(E33+E34)*1.055 -> 4.431 | F40: =(F33+F34)*1.055 -> 4.5365 | H40: GJ to Mcf at 1.055. Roughly 48% of gas is priced at Dawn, Malin and Emerson rather than AECO, which is what the premium represents.
A41: Realised condensate and oil (C$/Bbl) | B41: =B32*B35+B36 -> 109.6 | C41: =C32*C35+C36 -> 102 | D41: =D32*D35+D36 -> 97.2 | E41: =E32*E35+E36 -> 94.5 | F41: =F32*F35+F36 -> 94.5 | H41: Validated on Q1 2026: actual C$96.27 vs WTI ~US$70 x 1.37 = C$95.9. Q2 2026 printed C$126.96 because WTI spiked on Hormuz disruption.
A42: Realised other NGLs (C$/Bbl) | B42: =B41*B43 -> 35.072 | C42: =C41*C43 -> 32.64 | D42: =D41*D43 -> 31.104 | E42: =E41*E43 -> 30.24 | F42: =F41*F43 -> 30.24
A43: Other NGLs as % of condensate price | B43: 0.32 | C43: 0.32 | D43: 0.32 | E43: 0.32 | F43: 0.32 | H43: Historical range roughly 30–36%. Ethane, propane and butane.
A45: PRODUCTION — ANNUAL AVERAGE BY ASSET (Boe/d)
B46: 2026E | C46: 2027E | D46: 2028E | E46: 2029E | F46: 2030E | H46: Note
A47: Willesden Green | B47: 32300 | C47: 41000 | D47: 47000 | E47: 50000 | F47: 50000 | H47: Q4 2026 implied ~42 kBoe/d as Alhambra phase 2 fills. Plateaus at the company's stated ~50 kBoe/d.
...

Sheet Production
A1: Production Forecast
A2: Asset volumes converted into gas, condensate and NGL streams. All links green to Assumptions.
A4: VOLUMES BY ASSET (Boe/d)
B5: 2026E | C5: 2027E | D5: 2028E | E5: 2029E | F5: 2030E | H5: Note
A6: Willesden Green | B6: =Assumptions!B47 -> 32300 | C6: =Assumptions!C47 -> 41000 | D6: =Assumptions!D47 -> 47000 | E6: =Assumptions!E47 -> 50000 | F6: =Assumptions!F47 -> 50000
A7: Kaybob | B7: =Assumptions!B48 -> 19300 | C7: =Assumptions!C48 -> 19000 | D7: =Assumptions!D48 -> 19000 | E7: =Assumptions!E48 -> 17000 | F7: =Assumptions!F48 -> 15500
A8: Sinclair | B8: =Assumptions!B49 -> 0 | C8: =Assumptions!C49 -> 3000 | D8: =Assumptions!D49 -> 45000 | E8: =Assumptions!E49 -> 55000 | F8: =Assumptions!F49 -> 58000
A9: Other properties | B9: =Assumptions!B50 -> 400 | C9: =Assumptions!C50 -> 400 | D9: =Assumptions!D50 -> 350 | E9: =Assumptions!E50 -> 300 | F9: =Assumptions!F50 -> 300
A10: Total (Boe/d) | B10: =SUM(B6:B9) -> 52000 | C10: =SUM(C6:C9) -> 63400 | D10: =SUM(D6:D9) -> 111350 | E10: =SUM(E6:E9) -> 122300 | F10: =SUM(F6:F9) -> 123800
A11: Year-over-year growth | B11: =B10/52133-1 -> -0.0025511672 | C11: =C10/B10-1 -> 0.21923077 | D11: =D10/C10-1 -> 0.75630915 | E11: =E10/D10-1 -> 0.098338572 | F11: =F10/E10-1 -> 0.012264922 | H11: 2026 growth is measured against the 2026 guidance midpoint reconstruction of 52,133 Boe/d.
A13: LIQUIDS AND GAS SPLIT (Boe/d)
B14: 2026E | C14: 2027E | D14: 2028E | E14: 2029E | F14: 2030E | H14: Note
A15: Willesden Green — liquids | B15: =B6*Assumptions!B55 -> 17765 | C15: =C6*Assumptions!C55 -> 22550 | D15: =D6*Assumptions!D55 -> 25850 | E15: =E6*Assumptions!E55 -> 27500 | F15: =F6*Assumptions!F55 -> 27500
A16: Kaybob — liquids | B16: =B7*Assumptions!B57 -> 7720 | C16: =C7*Assumptions!C57 -> 7600 | D16: =D7*Assumptions!D57 -> 7600 | E16: =E7*Assumptions!E57 -> 6800 | F16: =F7*Assumptions!F57 -> 6200
A17: Sinclair — liquids | B17: =B8*Assumptions!B59 -> 0 | C17: =C8*Assumptions!C59 -> 300 | D17: =D8*Assumptions!D59 -> 4500 | E17: =E8*Assumptions!E59 -> 5500 | F17: =F8*Assumptions!F59 -> 5800
A18: Other — liquids | B18: =B9*Assumptions!B61 -> 120 | C18: =C9*Assumptions!C61 -> 120 | D18: =D9*Assumptions!D61 -> 105 | E18: =E9*Assumptions!E61 -> 90 | F18: =F9*Assumptions!F61 -> 90
A19: Total liquids (Bbl/d) | B19: =SUM(B15:B18) -> 25605 | C19: =SUM(C15:C18) -> 30570 | D19: =SUM(D15:D18) -> 38055 | E19: =SUM(E15:E18) -> 39890 | F19: =SUM(F15:F18) -> 39590
A20: Total natural gas (Boe/d) | B20: =B10-B19 -> 26395 | C20: =C10-C19 -> 32830 | D20: =D10-D19 -> 73295 | E20: =E10-E19 -> 82410 | F20: =F10-F19 -> 84210
A21: Liquids as % of total | B21: =B19/B10 -> 0.49240385 | C21: =C19/C10 -> 0.48217666 | D21: =D19/D10 -> 0.34176022 | E21: =E19/E10 -> 0.32616517 | F21: =F19/F10 -> 0.31978998 | H21: Watch this fall as Sinclair dry gas arrives. It is the reason revenue per Boe declines even as volumes double.
A23: SALES STREAMS
B24: 2026E | C24: 2027E | D24: 2028E | E24: 2029E | F24: 2030E | H24: Note
A25: Willesden Green — condensate | B25: =B15*Assumptions!B56 -> 14212 | C25: =C15*Assumptions!C56 -> 18040 | D25: =D15*Assumptions!D56 -> 20680 | E25: =E15*Assumptions!E56 -> 22000 | F25: =F15*Assumptions!F56 -> 22000
A26: Kaybob — condensate | B26: =B16*Assumptions!B58 -> 5404 | C26: =C16*Assumptions!C58 -> 5320 | D26: =D16*Assumptions!D58 -> 5320 | E26: =E16*Assumptions!E58 -> 4760 | F26: =F16*Assumptions!F58 -> 4340
A27: Sinclair — condensate | B27: =B17*Assumptions!B60 -> 0 | C27: =C17*Assumptions!C60 -> 225 | D27: =D17*Assumptions!D60 -> 3375 | E27: =E17*Assumptions!E60 -> 4125 | F27: =F17*Assumptions!F60 -> 4350
A28: Other — condensate | B28: =B18*Assumptions!B62 -> 84 | C28: =C18*Assumptions!C62 -> 84 | D28: =D18*Assumptions!D62 -> 73.5 | E28: =E18*Assumptions!E62 -> 63 | F28: =F18*Assumptions!F62 -> 63
A29: Condensate and oil (Bbl/d) | B29: =SUM(B25:B28) -> 19700 | C29: =SUM(C25:C28) -> 23669 | D29: =SUM(D25:D28) -> 29448.5 | E29: =SUM(E25:E28) -> 30948 | F29: =SUM(F25:F28) -> 30753
A30: Other NGLs (Bbl/d) | B30: =B19-B29 -> 5905 | C30: =C19-C29 -> 6901 | D30: =D19-D29 -> 8606.5 | E30: =E19-E29 -> 8942 | F30: =F19-F29 -> 8837
A31: Natural gas (MMcf/d) | B31: =B20*6/1000 -> 158.37 | C31: =C20*6/1000 -> 196.98 | D31: =D20*6/1000 -> 439.77 | E31: =E20*6/1000 -> 494.46 | F31: =F20*6/1000 -> 505.26 | H31: Sanity check: FY2025 actual was 131.9 MMcf/d; Q2 2026 was 144.4 MMcf/d.
A33: Check — streams reconvert to total Boe/d | B33: =B31*1000/6+B29+B30-B10 -> 0 | C33: =C31*1000/6+C29+C30-C10 -> 0 | D33: =D31*1000/6+D29+D30-D10 -> 0 | E33: =E31*1000/6+E29+E30-E10 -> 0 | F33: =F31*1000/6+F29+F30-F10 -> 0 | H33: Must be zero in every column.

Sheet Revenue_Netback
A1: Revenue and Netback
A2: Volumes times realised prices, less royalties, operating and transportation costs.
A4: REVENUE (C$mm)
B5: 2026E | C5: 2027E | D5: 2028E | E5: 2029E | F5: 2030E | H5: Note
A6: Natural gas | B6: =Production!B31*1000*Assumptions!B40*365/1000000 -> 201.24828 | C6: =Production!C31*1000*Assumptions!C40*365/1000000 -> 288.23788 | D6: =Production!D31*1000*Assumptions!D40*365/1000000 -> 694.31217 | E6: =Production!E31*1000*Assumptions!E40*365/1000000 -> 799.69757 | F6: =Production!F31*1000*Assumptions!F40*365/1000000 -> 836.62088
A7: Condensate and oil | B7: =Production!B29*Assumptions!B41*365/1000000 -> 788.0788 | C7: =Production!C29*Assumptions!C41*365/1000000 -> 881.19687 | D7: =Production!D29*Assumptions!D41*365/1000000 -> 1044.7739 | E7: =Production!E29*Assumptions!E41*365/1000000 -> 1067.4739 | F7: =Production!F29*Assumptions!F41*365/1000000 -> 1060.7479
A8: Other NGLs | B8: =Production!B30*Assumptions!B42*365/1000000 -> 75.591558 | C8: =Production!C30*Assumptions!C42*365/1000000 -> 82.215754 | D8: =Production!D30*Assumptions!D42*365/1000000 -> 97.70925 | E8: =Production!E30*Assumptions!E42*365/1000000 -> 98.698219 | F8: =Production!F30*Assumptions!F42*365/1000000 -> 97.539271
A9: Petroleum and natural gas sales | B9: =SUM(B6:B8) -> 1064.9186 | C9: =SUM(C6:C8) -> 1251.6505 | D9: =SUM(D6:D8) -> 1836.7953 | E9: =SUM(E6:E8) -> 1965.8697 | F9: =SUM(F6:F8) -> 1994.908
A10: Revenue per Boe (C$) | B10: =B9*1000000/Production!B10/365 -> 56.10741 | C10: =C9*1000000/Production!C10/365 -> 54.088004 | D10: =D9*1000000/Production!D10/365 -> 45.193677 | E10: =E9*1000000/Production!E10/365 -> 44.038793 | F10: =F9*1000000/Production!F10/365 -> 44.14783 | H10: Q2 2026 actual was C$60.59/Boe. Expect this to fall as Sinclair gas dilutes the mix.
A12: NETBACK (C$mm)
B13: 2026E | C13: 2027E | D13: 2028E | E13: 2029E | F13: 2030E | H13: Note
A14: Royalties | B14: =-B9*Assumptions!B66 -> -58.570525 | C14: =-C9*Assumptions!C66 -> -75.09903 | D14: =-D9*Assumptions!D66 -> -128.57567 | E14: =-E9*Assumptions!E66 -> -157.26957 | F14: =-F9*Assumptions!F66 -> -169.56718
A15: Operating expense | B15: =-Production!B10*Assumptions!B67*365/1000000 -> -161.33 | C15: =-Production!C10*Assumptions!C67*365/1000000 -> -179.34275 | D15: =-Production!D10*Assumptions!D67*365/1000000 -> -274.33856 | E15: =-Production!E10*Assumptions!E67*365/1000000 -> -278.99687 | F15: =-Production!F10*Assumptions!F67*365/1000000 -> -275.6407
A16: Transportation and NGLs processing | B16: =-Production!B10*Assumptions!B68*365/1000000 -> -90.155 | C16: =-Production!C10*Assumptions!C68*365/1000000 -> -106.4486 | D16: =-Production!D10*Assumptions!D68*365/1000000 -> -172.73169 | E16: =-Production!E10*Assumptions!E68*365/1000000 -> -183.02195 | F16: =-Production!F10*Assumptions!F68*365/1000000 -> -183.00735
A17: Operating netback | B17: =B9+SUM(B14:B16) -> 754.86311 | C17: =C9+SUM(C14:C16) -> 890.76012 | D17: =D9+SUM(D14:D16) -> 1261.1494 | E17: =E9+SUM(E14:E16) -> 1346.5813 | F17: =F9+SUM(F14:F16) -> 1366.6928
A18: Risk management settlements | B18: =Production!B10*Assumptions!B70*365/1000000 -> -28.47 | C18: =Production!C10*Assumptions!C70*365/1000000 -> -17.35575 | D18: =Production!D10*Assumptions!D70*365/1000000 -> 0 | E18: =Production!E10*Assumptions!E70*365/1000000 -> 0 | F18: =Production!F10*Assumptions!F70*365/1000000 -> 0
A19: Netback including risk management | B19: =B17+B18 -> 726.39311 | C19: =C17+C18 -> 873.40437 | D19: =D17+D18 -> 1261.1494 | E19: =E17+E18 -> 1346.5813 | F19: =F17+F18 -> 1366.6928
A20: Netback per Boe (C$) | B20: =B19*1000000/Production!B10/365 -> 38.271502 | C20: =C19*1000000/Production!C10/365 -> 37.742724 | D20: =D19*1000000/Production!D10/365 -> 31.030119 | E20: =E19*1000000/Production!E10/365 -> 30.165689 | F20: =F19*1000000/Production!F10/365 -> 30.245265 | H20: FY2025 actual was C$31.96 including hedges; Q2 2026 was C$41.69. This is the headline unit economic.

Sheet Cash_Flow
A1: Adjusted Funds Flow and Free Cash Flow
A2: Netback less corporate costs, then capital. The net cash rollforward is the solvency test.
A4: ADJUSTED FUNDS FLOW (C$mm)
B5: 2026E | C5: 2027E | D5: 2028E | E5: 2029E | F5: 2030E | H5: Note
A6: Netback including risk management | B6: =Revenue_Netback!B19 -> 726.39311 | C6: =Revenue_Netback!C19 -> 873.40437 | D6: =Revenue_Netback!D19 -> 1261.1494 | E6: =Revenue_Netback!E19 -> 1346.5813 | F6: =Revenue_Netback!F19 -> 1366.6928
A7: General and administrative | B7: =-Production!B10*Assumptions!B69*365/1000000 -> -30.368 | C7: =-Production!C10*Assumptions!C69*365/1000000 -> -32.3974 | D7: =-Production!D10*Assumptions!D69*365/1000000 -> -40.64275 | E7: =-Production!E10*Assumptions!E69*365/1000000 -> -40.17555 | F7: =-Production!F10*Assumptions!F69*365/1000000 -> -40.6683
A8: Net interest income / (expense) | B8: =Assumptions!B72 -> 12 | C8: =Assumptions!C72 -> 4 | D8: =Assumptions!D72 -> -8 | E8: =Assumptions!E72 -> -6 | F8: =Assumptions!F72 -> 0
A9: Pre-tax cash flow | B9: =SUM(B6:B8) -> 708.02511 | C9: =SUM(C6:C8) -> 845.00697 | D9: =SUM(D6:D8) -> 1212.5066 | E9: =SUM(E6:E8) -> 1300.4057 | F9: =SUM(F6:F8) -> 1326.0245
A10: Cash taxes | B10: =-MAX(0,B9)*Assumptions!B71 -> 0 | C10: =-MAX(0,C9)*Assumptions!C71 -> 0 | D10: =-MAX(0,D9)*Assumptions!D71 -> -60.625332 | E10: =-MAX(0,E9)*Assumptions!E71 -> -156.04869 | F10: =-MAX(0,F9)*Assumptions!F71 -> -238.6844
A11: Adjusted funds flow | B11: =B9+B10 -> 708.02511 | C11: =C9+C10 -> 845.00697 | D11: =D9+D10 -> 1151.8813 | E11: =E9+E10 -> 1144.357 | F11: =F9+F10 -> 1087.3401
A12: Adjusted funds flow per share (C$) | B12: =B11/Assumptions!B79 -> 4.8561393 | C12: =C11/Assumptions!C79 -> 5.7956582 | D12: =D11/Assumptions!D79 -> 7.9004205 | E12: =E11/Assumptions!E79 -> 7.8488138 | F12: =F11/Assumptions!F79 -> 7.4577508
A14: FREE CASH FLOW (C$mm)
B15: 2026E | C15: 2027E | D15: 2028E | E15: 2029E | F15: 2030E | H15: Note
A16: Capital expenditures | B16: =-Assumptions!B76 -> -1050 | C16: =-Assumptions!C76 -> -1000 | D16: =-Assumptions!D76 -> -800 | E16: =-Assumptions!E76 -> -700 | F16: =-Assumptions!F76 -> -700
A17: Abandonment and reclamation | B17: =-Assumptions!B77 -> -35 | C17: =-Assumptions!C77 -> -35 | D17: =-Assumptions!D77 -> -40 | E17: =-Assumptions!E77 -> -40 | F17: =-Assumptions!F77 -> -45
A18: Free cash flow before dividends | B18: =B11+B16+B17 -> -376.97489 | C18: =C11+C16+C17 -> -189.99303 | D18: =D11+D16+D17 -> 311.8813 | E18: =E11+E16+E17 -> 404.35705 | F18: =F11+F16+F17 -> 342.34007
A19: Dividends | B19: =-Assumptions!B78*Assumptions!B79 -> -87.48 | C19: =-Assumptions!C78*Assumptions!C79 -> -87.48 | D19: =-Assumptions!D78*Assumptions!D79 -> -87.48 | E19: =-Assumptions!E78*Assumptions!E79 -> -87.48 | F19: =-Assumptions!F78*Assumptions!F79 -> -87.48
A20: Free cash flow after dividends | B20: =B18+B19 -> -464.45489 | C20: =C18+C19 -> -277.47303 | D20: =D18+D19 -> 224.4013 | E20: =E18+E19 -> 316.87705 | F20: =F18+F19 -> 254.86007
A21: Capital intensity (capex / AFF) | B21: =IFERROR(-B16/B11,"n/m") -> 1.4829982 | C21: =IFERROR(-C16/C11,"n/m") -> 1.1834222 | D21: =IFERROR(-D16/D11,"n/m") -> 0.694516 | E21: =IFERROR(-E16/E11,"n/m") -> 0.6116972 | F21: =IFERROR(-F16/F11,"n/m") -> 0.64377284 | H21: Above 1.0x is outspend. The year this crosses below 1.0x is when the equity story changes.
A23: NET CASH / (NET DEBT) ROLLFORWARD (C$mm)
B24: 2026E | C24: 2027E | D24: 2028E | E24: 2029E | F24: 2030E | H24: Note
A25: Opening net cash / (net debt) | B25: =Assumptions!B80 -> 672.8 | C25: =B27 -> 208.34511 | D25: =C27 -> -69.127912 | E25: =D27 -> 155.27339 | F25: =E27 -> 472.15044
A26: Free cash flow after dividends | B26: =B20 -> -464.45489 | C26: =C20 -> -277.47303 | D26: =D20 -> 224.4013 | E26: =E20 -> 316.87705 | F26: =F20 -> 254.86007
A27: Closing net cash / (net debt) | B27: =B25+B26 -> 208.34511 | C27: =C25+C26 -> -69.127912 | D27: =D25+D26 -> 155.27339 | E27: =E25+E26 -> 472.15044 | F27: =F25+F26 -> 727.0105 | H27: Negative means net debt. Compare against C$750mm of undrawn facilities — that is the true liquidity runway.
A29: Net debt / AFF | B29: =IFERROR(MAX(0,-B27)/B11,"n/m") -> 0 | C29: =IFERROR(MAX(0,-C27)/C11,"n/m") -> 0.081807505 | D29: =IFERROR(MAX(0,-D27)/D11,"n/m") -> 0 | E29: =IFERROR(MAX(0,-E27)/E11,"n/m") -> 0 | F29: =IFERROR(MAX(0,-F27)/F11,"n/m") -> 0 | H29: Canadian producers are generally uncomfortable above 1.5x. Watch the trough year.

Sheet Summary
A1: Output Summary & Guidance Checks
A2: The numbers you quote in a pitch, plus automatic tests that the model respects company guidance.
A4: KEY OUTPUTS
B5: 2026E | C5: 2027E | D5: 2028E | E5: 2029E | F5: 2030E | H5: Note
A6: Production (Boe/d) | B6: =Production!B10 -> 52000 | C6: =Production!C10 -> 63400 | D6: =Production!D10 -> 111350 | E6: =Production!E10 -> 122300 | F6: =Production!F10 -> 123800
A7: Liquids % | B7: =Production!B21 -> 0.49240385 | C7: =Production!C21 -> 0.48217666 | D7: =Production!D21 -> 0.34176022 | E7: =Production!E21 -> 0.32616517 | F7: =Production!F21 -> 0.31978998
A8: Revenue (C$mm) | B8: =Revenue_Netback!B9 -> 1064.9186 | C8: =Revenue_Netback!C9 -> 1251.6505 | D8: =Revenue_Netback!D9 -> 1836.7953 | E8: =Revenue_Netback!E9 -> 1965.8697 | F8: =Revenue_Netback!F9 -> 1994.908
A9: Netback (C$/Boe) | B9: =Revenue_Netback!B20 -> 38.271502 | C9: =Revenue_Netback!C20 -> 37.742724 | D9: =Revenue_Netback!D20 -> 31.030119 | E9: =Revenue_Netback!E20 -> 30.165689 | F9: =Revenue_Netback!F20 -> 30.245265
A10: Adjusted funds flow (C$mm) | B10: =Cash_Flow!B11 -> 708.02511 | C10: =Cash_Flow!C11 -> 845.00697 | D10: =Cash_Flow!D11 -> 1151.8813 | E10: =Cash_Flow!E11 -> 1144.357 | F10: =Cash_Flow!F11 -> 1087.3401
A11: Capital expenditures (C$mm) | B11: =Assumptions!B76 -> 1050 | C11: =Assumptions!C76 -> 1000 | D11: =Assumptions!D76 -> 800 | E11: =Assumptions!E76 -> 700 | F11: =Assumptions!F76 -> 700
A12: Free cash flow before dividends (C$mm) | B12: =Cash_Flow!B18 -> -376.97489 | C12: =Cash_Flow!C18 -> -189.99303 | D12: =Cash_Flow!D18 -> 311.8813 | E12: =Cash_Flow!E18 -> 404.35705 | F12: =Cash_Flow!F18 -> 342.34007
A13: Closing net cash / (net debt) (C$mm) | B13: =Cash_Flow!B27 -> 208.34511 | C13: =Cash_Flow!C27 -> -69.127912 | D13: =Cash_Flow!D27 -> 155.27339 | E13: =Cash_Flow!E27 -> 472.15044 | F13: =Cash_Flow!F27 -> 727.0105
A15: SANITY CHECKS AGAINST COMPANY GUIDANCE
A16: Test | B16: Model | C16: Guidance low | D16: Guidance high | E16: Result
A17: 2026E production (Boe/d) | B17: =B6 -> 52000 | C17: 51000 | D17: 53000 | E17: =IF(AND(B17>=C17,B17<=D17),"IN RANGE","OUTSIDE — REVIEW") -> IN RANGE
A18: 2027E production (Boe/d) | B18: =C6 -> 63400 | C18: 60000 | D18: 65000 | E18: =IF(AND(B18>=C18,B18<=D18),"IN RANGE","OUTSIDE — REVIEW") -> IN RANGE
A19: 2026E capital expenditures (C$mm) | B19: =B11 -> 1050 | C19: 1000 | D19: 1100 | E19: =IF(AND(B19>=C19,B19<=D19),"IN RANGE","OUTSIDE — REVIEW") -> IN RANGE
A20: 2027E capital expenditures (C$mm) | B20: =C11 -> 1000 | C20: 950 | D20: 1050 | E20: =IF(AND(B20>=C20,B20<=D20),"IN RANGE","OUTSIDE — REVIEW") -> IN RANGE
A22: Stream reconciliation (must be zero) | B22: =SUM(Production!B33:F33) -> 0 | E22: =IF(ABS(B22)<0.01,"OK","ERROR") -> OK
A24: WHAT THE MODEL SAYS — fill in after running all three scenarios
A25: 1. Production roughly doubles by 2029 on the Sinclair build-out, but liquids weighting falls, so netback per Boe compresses.
A26: 2. The outspend persists through 2027. Check the trough year on the net cash rollforward against C$750mm of undrawn facilities.
A27: 3. Run the Bear case. If the trough net debt exceeds available liquidity, the equity story depends on capital markets access, not operations.
