Workbook

Sheet README
A1: Paramount Resources — Module 4: Sum-of-the-Parts Net Asset Value
A2: Values each asset separately, then rolls to a per-share number and compares it to the market price.
A4: APPROACH
A5: Why sum-of-the-parts | B5: Paramount's assets have completely different economics: Willesden Green is a producing liquids-rich play, Sinclair is an unbuilt dry-gas project, Kaybob is a declining annuity, and the land bank generates nothing. A single corporate multiple would obscure all of that.
A6: Willesden Green | B6: Producing base as a declining annuity, plus the present value of a 20-year drilling programme valued off the Module 3 type curve. Net present value per well is live to the price deck rather than hardcoded.
A7: Sinclair | B7: Treated as a development project: remaining construction capital deducted, then a delayed annuity from first gas, multiplied by an execution risk factor. This is the asset that decides the valuation.
A8: Kaybob | B8: Declining annuity net of the maintenance capital required to sustain it.
A9: Land | B9: Acreage carrying no reserves, at a per-acre mark. The softest number in the model — treat it as option value, not value.
A10: Closed-form maths | B10: Every asset uses annuity algebra rather than a year-by-year grid. That keeps the sensitivity table on NAV_Summary fully live instead of static.
A12: THE TWO FORMULAS DOING ALL THE WORK
A13: Declining annuity | B13: PV = Q x 365 x netback / (r + d). A stream declining at rate d, discounted at r. This is why the decline rate matters as much as the discount rate — both sit in the denominator.
A14: Level annuity | B14: PV = C x [1 - (1+r)^-n] / r. Used for the drilling programme: a fixed number of wells drilled each year for n years.
A16: HEALTH WARNINGS
A17: • This is a pre-tax-pool NAV with a single effective tax drag applied at the corporate level. A full model would schedule the tax pools remaining from the Grande Prairie disposition explicitly.
A18: • The Sinclair execution risk factor is a judgement, not an observation. It is the single largest lever in the file — vary it before quoting any conclusion.
A19: • Land value is the weakest input. Frontier acreage in Horn River, Liard and the Northwest Territories may be worth nothing at current prices.
A20: • Module 3 showed the drilling programme assumes no well-to-well interference, so the well count is a floor and the programme value is therefore optimistic at the margin.
A22: Hypothetical case study. Not investment advice.

Sheet Assumptions
A1: Valuation Assumptions
A2: Yellow cells are the levers. Netbacks are computed from the price deck and each asset's product mix.
A4: PRICE DECK AND DISCOUNTING
A5: WTI (US$/Bbl) | B5: 80 | E5: Module 2 Base deck long-run level. Spot is near US$86 on a geopolitical premium.
A6: CAD/USD | B6: 1.36
A7: Realised gas (C$/Mcf) | B7: 4.33 | E7: AECO C$3.20/GJ plus C$0.90 diversification premium, converted at 1.055.
A8: Other NGLs as % of condensate | B8: 0.32
A9: Discount rate | B9: 0.1 | E9: Industry convention for reserve valuation is 10% before tax.
A10: Shares outstanding (mm) | B10: 145.8
A11: Current share price (C$) | B11: 32.65
A13: ASSET MIX AND UNIT COSTS
B14: Willesden Grn | C14: Sinclair | D14: Kaybob
A15: Liquids % of production | B15: 0.55 | C15: 0.1 | D15: 0.4 | E15: Sinclair is dry gas — this single row explains most of the valuation gap between the assets.
A16: Condensate share of liquids | B16: 0.8 | C16: 0.75 | D16: 0.7
A17: Operating expense (C$/Boe) | B17: 4.71 | C17: 4 | D17: 11 | E17: Willesden Green is the Q4 2025 actual. Sinclair assumes high-rate dry gas through an owned plant.
A18: Transportation (C$/Boe) | B18: 4.75 | C18: 4.5 | D18: 5
A19: Royalty rate | B19: 0.06 | C19: 0.06 | D19: 0.08
A21: COMPUTED NETBACK BY ASSET (C$/Boe)
B22: Willesden Grn | C22: Sinclair | D22: Kaybob
A23: Condensate price (C$/Bbl) | B23: =Assumptions!$B$5*Assumptions!$B$6 -> 108.8 | C23: =Assumptions!$B$5*Assumptions!$B$6 -> 108.8 | D23: =Assumptions!$B$5*Assumptions!$B$6 -> 108.8
A24: Revenue per Boe | B24: =B15*B16*B23+B15*(1-B16)*B23*Assumptions!$B$8+(1-B15)*6*Assumptions!$B$7 -> 63.39276 | C24: =C15*C16*C23+C15*(1-C16)*C23*Assumptions!$B$8+(1-C15)*6*Assumptions!$B$7 -> 32.4124 | D24: =D15*D16*D23+D15*(1-D16)*D23*Assumptions!$B$8+(1-D15)*6*Assumptions!$B$7 -> 50.22992 | E24: One Boe = liquids fraction in barrels, plus the gas remainder times six Mcf.
A25: Netback per Boe | B25: =B24*(1-B19)-B17-B18 -> 50.129194 | C25: =C24*(1-C19)-C17-C18 -> 21.967656 | D25: =D24*(1-D19)-D17-D18 -> 30.211526 | E25: Drives every asset value below.
A27: WILLESDEN GREEN — PRODUCING BASE AND DRILLING PROGRAMME
A28: Current production (Boe/d) | B28: 27466 | E28: Q2 2026 actual.
A29: Base decline rate | B29: 0.28 | E29: Corporate-level decline on the producing base, gentler than a single new well.
A30: EUR per well (MBoe) | B30: 1441 | E30: MODULE 3 OUTPUT — calibrated to the disclosed 210-day rate.
A31: Production PV factor | B31: 0.57 | E31: Collapses the timing of a well's production into one discount factor. Calibrated so NPV per well reproduces the Module 3 full-cycle figure of C$23.5mm.
A32: Full-cycle cost per well (C$mm) | B32: 18 | E32: MODULE 3: C$13mm drilling and completion plus C$5mm allocated facility capital.
A33: Net present value per well (C$mm) | B33: =Assumptions!$B$30*1000*B25*Assumptions!$B$31/1000000-Assumptions!$B$32 -> 23.174616 | E33: Live to price. Cross-check against Module 3's C$23.5mm at WTI US$80.
A34: Wells drilled per year | B34: 16 | E34: MODULE 3: the count that sustains the 50,000 Boe/d plateau. Assumes no well interference, so it is a floor.
A35: Programme life (years) | B35: 20 | E35: Company states the plateau is sustainable for 20+ years.
A36: Risk factor on undrilled locations | B36: 0.8 | E36: Haircut for locations not yet booked as proved developed.
A38: SINCLAIR — DEVELOPMENT PROJECT
A39: Plateau production (Boe/d) | B39: 55000 | E39: Constrained by 335 MMcf/d of firm egress, not by the resource.
A40: Years held at plateau | B40: 10 | E40: Egress is capped at 335 MMcf/d while the resource is far larger, so the asset is designed to hold plateau rather than decline from day one. Modelling immediate decline understates it badly.
A41: Decline rate after plateau | B41: 0.15
A42: Remaining construction capital (C$mm) | B42: 800 | E42: Roughly C$360mm in 2026 plus C$440mm in 2027 per company guidance.
A43: Years to first gas | B43: 1.4 | E43: Q4 2027 from an August 2026 valuation date.
A44: Years to reach plateau | B44: 2
A45: Maintenance capital (% of netback) | B45: 0.3 | E45: Dry gas needs continuous drilling to hold plateau.
...

Sheet NAV_Build
A1: Asset-by-Asset Net Asset Value
A2: Closed-form annuities. Every value is live to the Assumptions sheet.
A4: WILLESDEN GREEN
A5: Producing base — declining annuity (C$mm) | B5: =Assumptions!$B$28*365*Assumptions!B25/(Assumptions!$B$9+Assumptions!$B$29)/1000000 -> 1322.4992 | E5: Q x 365 x netback / (r + d).
A6: Drilling programme — level annuity (C$mm) | B6: =Assumptions!$B$34*Assumptions!$B$33*Assumptions!$B$36*(1-(1+Assumptions!$B$9)^-Assumptions!$B$35)/Assumptions!$B$9 -> 2525.4217 | E6: Wells per year x risked net present value per well, as a 20-year annuity.
A7: Willesden Green total (C$mm) | B7: =B5+B6 -> 3847.9209
A9: SINCLAIR
A10: Annual cash flow at plateau (C$mm) | B10: =Assumptions!$B$39*365*Assumptions!C25*(1-Assumptions!$B$45)/1000000 -> 308.70049 | E10: Net of the maintenance capital needed to hold the plateau.
A11: Value at first gas: plateau annuity plus declining tail (C$mm) | B11: =B10*(1-(1+Assumptions!$B$9)^-Assumptions!$B$40)/Assumptions!$B$9+B10/(Assumptions!$B$9+Assumptions!$B$41)*(1+Assumptions!$B$9)^-Assumptions!$B$40 -> 2372.9005 | E11: Level annuity across the plateau years, then a declining perpetuity discounted back.
A12: Discounted to today (C$mm) | B12: =B11/(1+Assumptions!$B$9)^(Assumptions!$B$43+Assumptions!$B$44/2) -> 1887.7178 | E12: Start-up delay plus half the ramp period.
A13: Less: remaining construction capital (C$mm) | B13: =-Assumptions!$B$42/(1+Assumptions!$B$9)^(Assumptions!$B$43/2) -> -748.36783
A14: Sinclair total, risked (C$mm) | B14: =(B12+B13)*Assumptions!$B$46 -> 797.545 | E14: Risk factor applied to the net project value, not to the gross cash flow.
A16: KAYBOB, LAND AND CORPORATE
A17: Kaybob — declining annuity net of maintenance (C$mm) | B17: =Assumptions!$B$49*365*Assumptions!D25*(1-Assumptions!$B$51)/(Assumptions!$B$9+Assumptions!$B$50)/1000000 -> 535.17793
A18: Undeveloped land (C$mm) | B18: =Assumptions!$B$52*1000*Assumptions!$B$53/1000000 -> 352.35
A19: Corporate overhead — perpetuity (C$mm) | B19: =-Assumptions!$B$56/Assumptions!$B$9 -> -600 | E19: Capitalised head office cost. Frequently omitted, which flatters NAV.
A20: Abandonment beyond reserves (C$mm) | B20: =-Assumptions!$B$59 -> -300
A22: ROLL-UP
A23: Gross asset value before tax (C$mm) | B23: =B7+B14+B17+B18+B19+B20 -> 4632.9938
A24: Less: tax drag (C$mm) | B24: =-MAX(0,B23)*Assumptions!$B$60 -> -555.95926
A25: After-tax asset value (C$mm) | B25: =B23+B24 -> 4077.0346
A26: Plus: net cash and investments (C$mm) | B26: =Assumptions!$B$57+Assumptions!$B$58 -> 537.1
A27: NET ASSET VALUE (C$mm) | B27: =B25+B26 -> 4614.1346
A28: NAV per share (C$) | B28: =B27/Assumptions!$B$10 -> 31.647014
A29: Price / NAV | B29: =Assumptions!$B$11/B28 -> 1.0316929 | E29: Above 1.0x means the market pays more than this model supports.
A30: Upside / (downside) to NAV | B30: =B28/Assumptions!$B$11-1 -> -0.03071934

Sheet NAV_Summary
A1: Valuation Summary
A2: Sum of the parts, contribution by asset, and live sensitivity to the two assumptions that matter most.
A4: SUM OF THE PARTS
A5: Asset | B5: C$mm | C5: C$/share | D5: % of gross
A6: Willesden Green | B6: =NAV_Build!B7 -> 3847.9209 | C6: =B6/Assumptions!$B$10 -> 26.391776 | D6: =B6/SUM($B$6:$B$11) -> 0.83054738
A7: Sinclair (risked) | B7: =NAV_Build!B14 -> 797.545 | C7: =B7/Assumptions!$B$10 -> 5.4701303 | D7: =B7/SUM($B$6:$B$11) -> 0.17214463
A8: Kaybob | B8: =NAV_Build!B17 -> 535.17793 | C8: =B8/Assumptions!$B$10 -> 3.6706305 | D8: =B8/SUM($B$6:$B$11) -> 0.11551449
A9: Undeveloped land | B9: =NAV_Build!B18 -> 352.35 | C9: =B9/Assumptions!$B$10 -> 2.4166667 | D9: =B9/SUM($B$6:$B$11) -> 0.076052335
A10: Corporate overhead | B10: =NAV_Build!B19 -> -600 | C10: =B10/Assumptions!$B$10 -> -4.1152263 | D10: =B10/SUM($B$6:$B$11) -> -0.12950589
A11: Abandonment | B11: =NAV_Build!B20 -> -300 | C11: =B11/Assumptions!$B$10 -> -2.0576132 | D11: =B11/SUM($B$6:$B$11) -> -0.064752946
A12: Gross asset value | B12: =SUM(B6:B11) -> 4632.9938 | C12: =SUM(C6:C11) -> 31.776364
A13: Tax drag | B13: =NAV_Build!B24 -> -555.95926 | C13: =B13/Assumptions!$B$10 -> -3.8131637
A14: Net cash and investments | B14: =NAV_Build!B26 -> 537.1 | C14: =B14/Assumptions!$B$10 -> 3.6838134
A15: NET ASSET VALUE | B15: =NAV_Build!B27 -> 4614.1346 | C15: =NAV_Build!B28 -> 31.647014
A17: VERSUS THE MARKET
A18: NAV per share (C$) | B18: =NAV_Build!B28 -> 31.647014
A19: Current share price (C$) | B19: =Assumptions!$B$11 -> 32.65
A20: Price / NAV | B20: =NAV_Build!B29 -> 1.0316929 | I20: Compare with 1.46x against before-tax 2P NPV10 in the Data Book. This NAV adds land and Sinclair upside but deducts tax, overhead and abandonment.
A21: Upside / (downside) | B21: =NAV_Build!B30 -> -0.03071934
A23: SENSITIVITY — NAV PER SHARE (C$)
A24: WTI (US$/Bbl) \ Sinclair execution risk | B24: 0.5 | C24: 0.6 | D24: 0.7 | E24: 0.8 | F24: 0.9
A25: 55 | B25: =((Assumptions!$B$28*365*((Assumptions!$B$15*Assumptions!$B$16*($A25*Assumptions!$B$6)+Assumptions!$B$15*(1-Assumptions!$B$16)*($A25*Assumptions!$B$6)*Assumptions!$B$8+(1-Assumptions!$B$15)*6*Assumptions!$B$7)*(1-Assumptions!$B$19)-Assumptions!$B$17-Assumptions!$B$18)/(Assumptions!$B$9+Assumptions!$B$29)/1000000+Assumptions!$B$34*(Assumptions!$B$30*1000*((Assumptions!$B$15*Assumptions!$B$16*($A25*Assumptions!$B$6)+Assumptions!$B$15*(1-Assumptions!$B$16)*($A25*Assumptions!$B$6)*Assumptions!$B$8+(1-Assumptions!$B$15)*6*Assumptions!$B$7)*(1-Assumptions!$B$19)-Assumptions!$B$17-Assumptions!$B$18)*Assumptions!$B$31/1000000-Assumptions!$B$32)*Assumptions!$B$36*(1-(1+Assumptions!$B$9)^-Assumptions!$B$35)/Assumptions!$B$9+(((Assumptions!$B$39*365*((Assumptions!$C$15*Assumptions!$C$16*($A25*Assumptions!$B$6)+Assumptions!$C$15*(1-Assumptions!$C$16)*($A25*Assumptions!$B$6)*Assumptions!$B$8+(1-Assumptions!$C$15)*6*Assumptions!$B$7)*(1-Assumptions!$C$19)-Assumptions!$C$17-Assumptions!$C$18)*(1-Assumptions!$B$45)/1000000)*(1-(1+Assumptions!$B$9)^-Assumptions!$B$40)/Assumptions!$B$9+(Assumptions!$B$39*365*((Assumptions!$C$15*Assumptions!$C$16*($A25*Assumptions!$B$6)+Assumptions!$C$15*(1-Assumptions!$C$16)*($A25*Assumptions!$B$6)*Assumptions!$B$8+(1-Assumptions!$C$15)*6*Assumptions!$B$7)*(1-Assumptions!$C$19)-Assumptions!$C$17-Assumptions!$C$18)*(1-Assumptions!$B$45)/1000000)/(Assumptions!$B$9+Assumptions!$B$41)*(1+Assumptions!$B$9)^-Assumptions!$B$40)/(1+Assumptions!$B$9)^(Assumptions!$B$43+Assumptions!$B$44/2)-Assumptions!$B$42/(1+Assumptions!$B$9)^(Assumptions!$B$43/2))*B$24+Assumptions!$B$49*365*((Assumptions!$D$15*Assumptions!$D$16*($A25*Assumptions!$B$6)+Assumptions!$D$15*(1-Assumptions!$D$16)*($A25*Assumptions!$B$6)*Assumptions!$B$8+(1-Assumptions!$D$15)*6*Assumptions!$B$7)*(1-Assumptions!$D$19)-Assumptions!$D$17-Assumptions!$D$18)*(1-Assumptions!$B$51)/(Assumptions!$B$9+Assumptions!$B$50)/1000000+Assumptions!$B$52*1000*Assumptions!$B$53/1000000-Assumptions!$B$56/Assumptions!$B$9-Assumptions!$B$59)*(1-Assumptions!$B$60)+Assumptions!$B$57+Assumptions!$B$58)/Assumptions!$B$10 -> 17.895772 | C25: =((Assumptions!$B$28*365*((Assumptions!$B$15*Assumptions!$B$16*($A25*Assumptions!$B$6)+Assumptions!$B$15*(1-Assumptions!$B$16)*($A25*Assumptions!$B$6)*Assumptions!$B$8+(1-Assumptions!$B$15)*6*Assumptions!$B$7)*(1-Assumptions!$B$19)-Assumptions!$B$17-Assumptions!$B$18)/(Assumptions!$B$9+Assumptions!$B$29)/1000000+Assumptions!$B$34*(Assumptions!$B$30*1000*((Assumptions!$B$15*Assumptions!$B$16*($A25*Assumptions!$B$6)+Assumptions!$B$15*(1-Assumptions!$B$16)*($A25*Assumptions!$B$6)*Assumptions!$B$8+(1-Assumptions!$B$15)*6*Assumptions!$B$7)*(1-Assumptions!$B$19)-Assumptions!$B$17-Assumptions!$B$18)*Assumptions!$B$31/1000000-Assumptions!$B$32)*Assumptions!$B$36*(1-(1+Assumptions!$B$9)^-Assumptions!$B$35)/Assumptions!$B$9+(((Assumptions!$B$39*365*((Assumptions!$C$15*Assumptions!$C$16*($A25*Assumptions!$B$6)+Assumptions!$C$15*(1-Assumptions!$C$16)*($A25*Assumptions!$B$6)*Assumptions!$B$8+(1-Assumptions!$C$15)*6*Assumptions!$B$7)*(1-Assumptions!$C$19)-Assumptions!$C$17-Assumptions!$C$18)*(1-Assumptions!$B$45)/1000000)*(1-(1+Assumptions!$B$9)^-Assumptions!$B$40)/Assumptions!$B$9+(Assumptions!$B$39*365*((Assumptions!$C$15*Assumptions!$C$16*($A25*Assumptions!$B$6)+Assumptions!$C$15*(1-Assumptions!$C$16)*($A25*Assumptions!$B$6)*Assumptions!$B$8+(1-Assumptions!$C$15)*6*Assumptions!$B$7)*(1-Assumptions!$C$19)-Assumptions!$C$17-Assumptions!$C$18)*(1-Assumptions!$B$45)/1000000)/(Assumptions!$B$9+Assumptions!$B$41)*(1+Assumptions!$B$9)^-Assumptions!$B$40)/(1+Assumptions!$B$9)^(Assumptions!$B$43+Assumptions!$B$44/2)-Assumptions!$B$42/(1+Assumptions!$B$9)^(Assumptions!$B$43/2))*C$24+Assumptions!$B$49*365*((Assumptions!$D$15*Assumptions!$D$16*($A25*Assumptions!$B$6)+Assumptions!$D$15*(1-Assumptions!$D$16)*($A25*Assumptions!$B$6)*Assumptions!$B$8+(1-Assumptions!$D$15)*6*Assumptions!$B$7)*(1-Assumptions!$D$19)-Assumptions!$D$17-Assumptions!$D$18)*(1-Assumptions!$B$51)/(Assumptions!$B$9+Assumptions!$B$50)/1000000+Assumptions!$B$52*1000*Assumptions!$B$53/1000000-Assumptions!$B$56/Assumptions!$B$9-Assumptions!$B$59)*(1-Assumptions!$B$60)+Assumptions!$B$57+Assumptions!$B$58)/Assumptions!$B$10 -> 18.445863 | D25: =((Assumptions!$B$28*365*((Assumptions!$B$15*Assumptions!$B$16*($A25*Assumptions!$B$6)+Assumptions!$B$15*(1-Assumptions!$B$16)*($A25*Assumptions!$B$6)*Assumptions!$B$8+(1-Assumptions!$B$15)*6*Assumptions!$B$7)*(1-Assumptions!$B$19)-Assumptions!$B$17-Assumptions!$B$18)/(Assumptions!$B$9+Assumptions!$B$29)/1000000+Assumptions!$B$34*(Assumptions!$B$30*1000*((Assumptions!$B$15*Assumptions!$B$16*($A25*Assumptions!$B$6)+Assumptions!$B$15*(1-Assumptions!$B$16)*($A25*Assumptions!$B$6)*Assumptions!$B$8+(1-Assumptions!$B$15)*6*Assumptions!$B$7)*(1-Assumptions!$B$19)-Assumptions!$B$17-Assumptions!$B$18)*Assumptions!$B$31/1000000-Assumptions!$B$32)*Assumptions!$B$36*(1-(1+Assumptions!$B$9)^-Assumptions!$B$35)/Assumptions!$B$9+(((Assumptions!$B$39*365*((Assumptions!$C$15*Assumptions!$C$16*($A25*Assumptions!$B$6)+Assumptions!$C$15*(1-Assumptions!$C$16)*($A25*Assumptions!$B$6)*Assumptions!$B$8+(1-Assumptions!$C$15)*6*Assumptions!$B$7)*(1-Assumptions!$C$19)-Assumptions!$C$17-Assumptions!$C$18)*(1-Assumptions!$B$45)/1000000)*(1-(1+Assumptions!$B$9)^-Assumptions!$B$40)/Assumptions!$B$9+(Assumptions!$B$39*365*((Assumptions!$C$15*Assumptions!$C$16*($A25*Assumptions!$B$6)+Assumptions!$C$15*(1-Assumptions!$C$16)*($A25*Assumptions!$B$6)*Assumptions!$B$8+(1-Assumptions!$C$15)*6*Assumptions!$B$7)*(1-Assumptions!$C$19)-Assumptions!$C$17-Assumptions!$C$18)*(1-Assumptions!$B$45)/1000000)/(Assumptions!$B$9+Assumptions!$B$41)*(1+Assumptions!$B$9)^-Assumptions!$B$40)/(1+Assumptions!$B$9)^(Assumptions!$B$43+Assumptions!$B$44/2)-Assumptions!$B$42/(1+Assumptions!$B$9)^(Assumptions!$B$43/2))*D$24+Assumptions!$B$49*365*((Assumptions!$D$15*Assumptions!$D$16*($A25*Assumptions!$B$6)+Assumptions!$D$15*(1-Assumptions!$D$16)*($A25*Assumptions!$B$6)*Assumptions!$B$8+(1-Assumptions!$D$15)*6*Assumptions!$B$7)*(1-Assumptions!$D$19)-Assumptions!$D$17-Assumptions!$D$18)*(1-Assumptions!$B$51)/(Assumptions!$B$9+Assumptions!$B$50)/1000000+Assumptions!$B$52*1000*Assumptions!$B$53/1000000-Assumptions!$B$56/Assumptions!$B$9-Assumptions!$B$59)*(1-Assumptions!$B$60)+Assumptions!$B$57+Assumptions!$B$58)/Assumptions!$B$10 -> 18.995954 | E25: =((Assumptions!$B$28*365*((Assumptions!$B$15*Assumptions!$B$16*($A25*Assumptions!$B$6)+Assumptions!$B$15*(1-Assumptions!$B$16)*($A25*Assumptions!$B$6)*Assumptions!$B$8+(1-Assumptions!$B$15)*6*Assumptions!$B$7)*(1-Assumptions!$B$19)-Assumptions!$B$17-Assumptions!$B$18)/(Assumptions!$B$9+Assumptions!$B$29)/1000000+Assumptions!$B$34*(Assumptions!$B$30*1000*((Assumptions!$B$15*Assumptions!$B$16*($A25*Assumptions!$B$6)+Assumptions!$B$15*(1-Assumptions!$B$16)*($A25*Assumptions!$B$6)*Assumptions!$B$8+(1-Assumptions!$B$15)*6*Assumptions!$B$7)*(1-Assumptions!$B$19)-Assumptions!$B$17-Assumptions!$B$18)*Assumptions!$B$31/1000000-Assumptions!$B$32)*Assumptions!$B$36*(1-(1+Assumptions!$B$9)^-Assumptions!$B$35)/Assumptions!$B$9+(((Assumptions!$B$39*365*((Assumptions!$C$15*Assumptions!$C$16*($A25*Assumptions!$B$6)+Assumptions!$C$15*(1-Assumptions!$C$16)*($A25*Assumptions!$B$6)*Assumptions!$B$8+(1-Assumptions!$C$15)*6*Assumptions!$B$7)*(1-Assumptions!$C$19)-Assumptions!$C$17-Assumptions!$C$18)*(1-Assumptions!$B$45)/1000000)*(1-(1+Assumptions!$B$9)^-Assumptions!$B$40)/Assumptions!$B$9+(Assumptions!$B$39*365*((Assumptions!$C$15*Assumptions!$C$16*($A25*Assumptions!$B$6)+Assumptions!$C$15*(1-Assumptions!$C$16)*($A25*Assumptions!$B$6)*Assumptions!$B$8+(1-Assumptions!$C$15)*6*Assumptions!$B$7)*(1-Assumptions!$C$19)-Assumptions!$C$17-Assumptions!$C$18)*(1-Assumptions!$B$45)/1000000)/(Assumptions!$B$9+Assumptions!$B$41)*(1+Assumptions!$B$9)^-Assumptions!$B$40)/(1+Assumptions!$B$9)^(Assumptions!$B$43+Assumptions!$B$44/2)-Assumptions!$B$42/(1+Assumptions!$B$9)^(Assumptions!$B$43/2))*E$24+Assumptions!$B$49*365*((Assumptions!$D$15*Assumptions!$D$16*($A25*Assumptions!$B$6)+Assumptions!$D$15*(1-Assumptions!$D$16)*($A25*Assumptions!$B$6)*Assumptions!$B$8+(1-Assumptions!$D$15)*6*Assumptions!$B$7)*(1-Assumptions!$D$19)-Assumptions!$D$17-Assumptions!$D$18)*(1-Assumptions!$B$51)/(Assumptions!$B$9+Assumptions!$B$50)/1000000+Assumptions!$B$52*1000*Assumptions!$B$53/1000000-Assumptions!$B$56/Assumptions!$B$9-Assumptions!$B$59)*(1-Assumptions!$B$60)+Assumptions!$B$57+Assumptions!$B$58)/Assumptions!$B$10 -> 19.546045 | F25: =((Assumptions!$B$28*365*((Assumptions!$B$15*Assumptions!$B$16*($A25*Assumptions!$B$6)+Assumptions!$B$15*(1-Assumptions!$B$16)*($A25*Assumptions!$B$6)*Assumptions!$B$8+(1-Assumptions!$B$15)*6*Assumptions!$B$7)*(1-Assumptions!$B$19)-Assumptions!$B$17-Assumptions!$B$18)/(Assumptions!$B$9+Assumptions!$B$29)/1000000+Assumptions!$B$34*(Assumptions!$B$30*1000*((Assumptions!$B$15*Assumptions!$B$16*($A25*Assumptions!$B$6)+Assumptions!$B$15*(1-Assumptions!$B$16)*($A25*Assumptions!$B$6)*Assumptions!$B$8+(1-Assumptions!$B$15)*6*Assumptions!$B$7)*(1-Assumptions!$B$19)-Assumptions!$B$17-Assumptions!$B$18)*Assumptions!$B$31/1000000-Assumptions!$B$32)*Assumptions!$B$36*(1-(1+Assumptions!$B$9)^-Assumptions!$B$35)/Assumptions!$B$9+(((Assumptions!$B$39*365*((Assumptions!$C$15*Assumptions!$C$16*($A25*Assumptions!$B$6)+Assumptions!$C$15*(1-Assumptions!$C$16)*($A25*Assumptions!$B$6)*Assumptions!$B$8+(1-Assumptions!$C$15)*6*Assumptions!$B$7)*(1-Assumptions!$C$19)-Assumptions!$C$17-Assumptions!$C$18)*(1-Assumptions!$B$45)/1000000)*(1-(1+Assumptions!$B$9)^-Assumptions!$B$40)/Assumptions!$B$9+(Assumptions!$B$39*365*((Assumptions!$C$15*Assumptions!$C$16*($A25*Assumptions!$B$6)+Assumptions!$C$15*(1-Assumptions!$C$16)*($A25*Assumptions!$B$6)*Assumptions!$B$8+(1-Assumptions!$C$15)*6*Assumptions!$B$7)*(1-Assumptions!$C$19)-Assumptions!$C$17-Assumptions!$C$18)*(1-Assumptions!$B$45)/1000000)/(Assumptions!$B$9+Assumptions!$B$41)*(1+Assumptions!$B$9)^-Assumptions!$B$40)/(1+Assumptions!$B$9)^(Assumptions!$B$43+Assumptions!$B$44/2)-Assumptions!$B$42/(1+Assumptions!$B$9)^(Assumptions!$B$43/2))*F$24+Assumptions!$B$49*365*((Assumptions!$D$15*Assumptions!$D$16*($A25*Assumptions!$B$6)+Assumptions!$D$15*(1-Assumptions!$D$16)*($A25*Assumptions!$B$6)*Assumptions!$B$8+(1-Assumptions!$D$15)*6*Assumptions!$B$7)*(1-Assumptions!$D$19)-Assumptions!$D$17-Assumptions!$D$18)*(1-Assumptions!$B$51)/(Assumptions!$B$9+Assumptions!$B$50)/1000000+Assumptions!$B$52*1000*Assumptions!$B$53/1000000-Assumptions!$B$56/Assumptions!$B$9-Assumptions!$B$59)*(1-Assumptions!$B$60)+Assumptions!$B$57+Assumptions!$B$58)/Assumptions!$B$10 -> 20.096136
A26: 65 | B26: =((Assumptions!$B$28*365*((Assumptions!$B$15*Assumptions!$B$16*($A26*Assumptions!$B$6)+Assumptions!$B$15*(1-Assumptions!$B$16)*($A26*Assumptions!$B$6)*Assumptions!$B$8+(1-Assumptions!$B$15)*6*Assumptions!$B$7)*(1-Assumptions!$B$19)-Assumptions!$B$17-Assumptions!$B$18)/(Assumptions!$B$9+Assumptions!$B$29)/1000000+Assumptions!$B$34*(Assumptions!$B$30*1000*((Assumptions!$B$15*Assumptions!$B$16*($A26*Assumptions!$B$6)+Assumptions!$B$15*(1-Assumptions!$B$16)*($A26*Assumptions!$B$6)*Assumptions!$B$8+(1-Assumptions!$B$15)*6*Assumptions!$B$7)*(1-Assumptions!$B$19)-Assumptions!$B$17-Assumptions!$B$18)*Assumptions!$B$31/1000000-Assumptions!$B$32)*Assumptions!$B$36*(1-(1+Assumptions!$B$9)^-Assumptions!$B$35)/Assumptions!$B$9+(((Assumptions!$B$39*365*((Assumptions!$C$15*Assumptions!$C$16*($A26*Assumptions!$B$6)+Assumptions!$C$15*(1-Assumptions!$C$16)*($A26*Assumptions!$B$6)*Assumptions!$B$8+(1-Assumptions!$C$15)*6*Assumptions!$B$7)*(1-Assumptions!$C$19)-Assumptions!$C$17-Assumptions!$C$18)*(1-Assumptions!$B$45)/1000000)*(1-(1+Assumptions!$B$9)^-Assumptions!$B$40)/Assumptions!$B$9+(Assumptions!$B$39*365*((Assumptions!$C$15*Assumptions!$C$16*($A26*Assumptions!$B$6)+Assumptions!$C$15*(1-Assumptions!$C$16)*($A26*Assumptions!$B$6)*Assumptions!$B$8+(1-Assumptions!$C$15)*6*Assumptions!$B$7)*(1-Assumptions!$C$19)-Assumptions!$C$17-Assumptions!$C$18)*(1-Assumptions!$B$45)/1000000)/(Assumptions!$B$9+Assumptions!$B$41)*(1+Assumptions!$B$9)^-Assumptions!$B$40)/(1+Assumptions!$B$9)^(Assumptions!$B$43+Assumptions!$B$44/2)-Assumptions!$B$42/(1+Assumptions!$B$9)^(Assumptions!$B$43/2))*B$24+Assumptions!$B$49*365*((Assumptions!$D$15*Assumptions!$D$16*($A26*Assumptions!$B$6)+Assumptions!$D$15*(1-Assumptions!$D$16)*($A26*Assumptions!$B$6)*Assumptions!$B$8+(1-Assumptions!$D$15)*6*Assumptions!$B$7)*(1-Assumptions!$D$19)-Assumptions!$D$17-Assumptions!$D$18)*(1-Assumptions!$B$51)/(Assumptions!$B$9+Assumptions!$B$50)/1000000+Assumptions!$B$52*1000*Assumptions!$B$53/1000000-Assumptions!$B$56/Assumptions!$B$9-Assumptions!$B$59)*(1-Assumptions!$B$60)+Assumptions!$B$57+Assumptions!$B$58)/Assumptions!$B$10 -> 22.84613 | C26: =((Assumptions!$B$28*365*((Assumptions!$B$15*Assumptions!$B$16*($A26*Assumptions!$B$6)+Assumptions!$B$15*(1-Assumptions!$B$16)*($A26*Assumptions!$B$6)*Assumptions!$B$8+(1-Assumptions!$B$15)*6*Assumptions!$B$7)*(1-Assumptions!$B$19)-Assumptions!$B$17-Assumptions!$B$18)/(Assumptions!$B$9+Assumptions!$B$29)/1000000+Assumptions!$B$34*(Assumptions!$B$30*1000*((Assumptions!$B$15*Assumptions!$B$16*($A26*Assumptions!$B$6)+Assumptions!$B$15*(1-Assumptions!$B$16)*($A26*Assumptions!$B$6)*Assumptions!$B$8+(1-Assumptions!$B$15)*6*Assumptions!$B$7)*(1-Assumptions!$B$19)-Assumptions!$B$17-Assumptions!$B$18)*Assumptions!$B$31/1000000-Assumptions!$B$32)*Assumptions!$B$36*(1-(1+Assumptions!$B$9)^-Assumptions!$B$35)/Assumptions!$B$9+(((Assumptions!$B$39*365*((Assumptions!$C$15*Assumptions!$C$16*($A26*Assumptions!$B$6)+Assumptions!$C$15*(1-Assumptions!$C$16)*($A26*Assumptions!$B$6)*Assumptions!$B$8+(1-Assumptions!$C$15)*6*Assumptions!$B$7)*(1-Assumptions!$C$19)-Assumptions!$C$17-Assumptions!$C$18)*(1-Assumptions!$B$45)/1000000)*(1-(1+Assumptions!$B$9)^-Assumptions!$B$40)/Assumptions!$B$9+(Assumptions!$B$39*365*((Assumptions!$C$15*Assumptions!$C$16*($A26*Assumptions!$B$6)+Assumptions!$C$15*(1-Assumptions!$C$16)*($A26*Assumptions!$B$6)*Assumptions!$B$8+(1-Assumptions!$C$15)*6*Assumptions!$B$7)*(1-Assumptions!$C$19)-Assumptions!$C$17-Assumptions!$C$18)*(1-Assumptions!$B$45)/1000000)/(Assumptions!$B$9+Assumptions!$B$41)*(1+Assumptions!$B$9)^-Assumptions!$B$40)/(1+Assumptions!$B$9)^(Assumptions!$B$43+Assumptions!$B$44/2)-Assumptions!$B$42/(1+Assumptions!$B$9)^(Assumptions!$B$43/2))*C$24+Assumptions!$B$49*365*((Assumptions!$D$15*Assumptions!$D$16*($A26*Assumptions!$B$6)+Assumptions!$D$15*(1-Assumptions!$D$16)*($A26*Assumptions!$B$6)*Assumptions!$B$8+(1-Assumptions!$D$15)*6*Assumptions!$B$7)*(1-Assumptions!$D$19)-Assumptions!$D$17-Assumptions!$D$18)*(1-Assumptions!$B$51)/(Assumptions!$B$9+Assumptions!$B$50)/1000000+Assumptions!$B$52*1000*Assumptions!$B$53/1000000-Assumptions!$B$56/Assumptions!$B$9-Assumptions!$B$59)*(1-Assumptions!$B$60)+Assumptions!$B$57+Assumptions!$B$58)/Assumptions!$B$10 -> 23.451254 | D26: =((Assumptions!$B$28*365*((Assumptions!$B$15*Assumptions!$B$16*($A26*Assumptions!$B$6)+Assumptions!$B$15*(1-Assumptions!$B$16)*($A26*Assumptions!$B$6)*Assumptions!$B$8+(1-Assumptions!$B$15)*6*Assumptions!$B$7)*(1-Assumptions!$B$19)-Assumptions!$B$17-Assumptions!$B$18)/(Assumptions!$B$9+Assumptions!$B$29)/1000000+Assumptions!$B$34*(Assumptions!$B$30*1000*((Assumptions!$B$15*Assumptions!$B$16*($A26*Assumptions!$B$6)+Assumptions!$B$15*(1-Assumptions!$B$16)*($A26*Assumptions!$B$6)*Assumptions!$B$8+(1-Assumptions!$B$15)*6*Assumptions!$B$7)*(1-Assumptions!$B$19)-Assumptions!$B$17-Assumptions!$B$18)*Assumptions!$B$31/1000000-Assumptions!$B$32)*Assumptions!$B$36*(1-(1+Assumptions!$B$9)^-Assumptions!$B$35)/Assumptions!$B$9+(((Assumptions!$B$39*365*((Assumptions!$C$15*Assumptions!$C$16*($A26*Assumptions!$B$6)+Assumptions!$C$15*(1-Assumptions!$C$16)*($A26*Assumptions!$B$6)*Assumptions!$B$8+(1-Assumptions!$C$15)*6*Assumptions!$B$7)*(1-Assumptions!$C$19)-Assumptions!$C$17-Assumptions!$C$18)*(1-Assumptions!$B$45)/1000000)*(1-(1+Assumptions!$B$9)^-Assumptions!$B$40)/Assumptions!$B$9+(Assumptions!$B$39*365*((Assumptions!$C$15*Assumptions!$C$16*($A26*Assumptions!$B$6)+Assumptions!$C$15*(1-Assumptions!$C$16)*($A26*Assumptions!$B$6)*Assumptions!$B$8+(1-Assumptions!$C$15)*6*Assumptions!$B$7)*(1-Assumptions!$C$19)-Assumptions!$C$17-Assumptions!$C$18)*(1-Assumptions!$B$45)/1000000)/(Assumptions!$B$9+Assumptions!$B$41)*(1+Assumptions!$B$9)^-Assumptions!$B$40)/(1+Assumptions!$B$9)^(Assumptions!$B$43+Assumptions!$B$44/2)-Assumptions!$B$42/(1+Assumptions!$B$9)^(Assumptions!$B$43/2))*D$24+Assumptions!$B$49*365*((Assumptions!$D$15*Assumptions!$D$16*($A26*Assumptions!$B$6)+Assumptions!$D$15*(1-Assumptions!$D$16)*($A26*Assumptions!$B$6)*Assumptions!$B$8+(1-Assumptions!$D$15)*6*Assumptions!$B$7)*(1-Assumptions!$D$19)-Assumptions!$D$17-Assumptions!$D$18)*(1-Assumptions!$B$51)/(Assumptions!$B$9+Assumptions!$B$50)/1000000+Assumptions!$B$52*1000*Assumptions!$B$53/1000000-Assumptions!$B$56/Assumptions!$B$9-Assumptions!$B$59)*(1-Assumptions!$B$60)+Assumptions!$B$57+Assumptions!$B$58)/Assumptions!$B$10 -> 24.056378 | E26: =((Assumptions!$B$28*365*((Assumptions!$B$15*Assumptions!$B$16*($A26*Assumptions!$B$6)+Assumptions!$B$15*(1-Assumptions!$B$16)*($A26*Assumptions!$B$6)*Assumptions!$B$8+(1-Assumptions!$B$15)*6*Assumptions!$B$7)*(1-Assumptions!$B$19)-Assumptions!$B$17-Assumptions!$B$18)/(Assumptions!$B$9+Assumptions!$B$29)/1000000+Assumptions!$B$34*(Assumptions!$B$30*1000*((Assumptions!$B$15*Assumptions!$B$16*($A26*Assumptions!$B$6)+Assumptions!$B$15*(1-Assumptions!$B$16)*($A26*Assumptions!$B$6)*Assumptions!$B$8+(1-Assumptions!$B$15)*6*Assumptions!$B$7)*(1-Assumptions!$B$19)-Assumptions!$B$17-Assumptions!$B$18)*Assumptions!$B$31/1000000-Assumptions!$B$32)*Assumptions!$B$36*(1-(1+Assumptions!$B$9)^-Assumptions!$B$35)/Assumptions!$B$9+(((Assumptions!$B$39*365*((Assumptions!$C$15*Assumptions!$C$16*($A26*Assumptions!$B$6)+Assumptions!$C$15*(1-Assumptions!$C$16)*($A26*Assumptions!$B$6)*Assumptions!$B$8+(1-Assumptions!$C$15)*6*Assumptions!$B$7)*(1-Assumptions!$C$19)-Assumptions!$C$17-Assumptions!$C$18)*(1-Assumptions!$B$45)/1000000)*(1-(1+Assumptions!$B$9)^-Assumptions!$B$40)/Assumptions!$B$9+(Assumptions!$B$39*365*((Assumptions!$C$15*Assumptions!$C$16*($A26*Assumptions!$B$6)+Assumptions!$C$15*(1-Assumptions!$C$16)*($A26*Assumptions!$B$6)*Assumptions!$B$8+(1-Assumptions!$C$15)*6*Assumptions!$B$7)*(1-Assumptions!$C$19)-Assumptions!$C$17-Assumptions!$C$18)*(1-Assumptions!$B$45)/1000000)/(Assumptions!$B$9+Assumptions!$B$41)*(1+Assumptions!$B$9)^-Assumptions!$B$40)/(1+Assumptions!$B$9)^(Assumptions!$B$43+Assumptions!$B$44/2)-Assumptions!$B$42/(1+Assumptions!$B$9)^(Assumptions!$B$43/2))*E$24+Assumptions!$B$49*365*((Assumptions!$D$15*Assumptions!$D$16*($A26*Assumptions!$B$6)+Assumptions!$D$15*(1-Assumptions!$D$16)*($A26*Assumptions!$B$6)*Assumptions!$B$8+(1-Assumptions!$D$15)*6*Assumptions!$B$7)*(1-Assumptions!$D$19)-Assumptions!$D$17-Assumptions!$D$18)*(1-Assumptions!$B$51)/(Assumptions!$B$9+Assumptions!$B$50)/1000000+Assumptions!$B$52*1000*Assumptions!$B$53/1000000-Assumptions!$B$56/Assumptions!$B$9-Assumptions!$B$59)*(1-Assumptions!$B$60)+Assumptions!$B$57+Assumptions!$B$58)/Assumptions!$B$10 -> 24.661502 | F26: =((Assumptions!$B$28*365*((Assumptions!$B$15*Assumptions!$B$16*($A26*Assumptions!$B$6)+Assumptions!$B$15*(1-Assumptions!$B$16)*($A26*Assumptions!$B$6)*Assumptions!$B$8+(1-Assumptions!$B$15)*6*Assumptions!$B$7)*(1-Assumptions!$B$19)-Assumptions!$B$17-Assumptions!$B$18)/(Assumptions!$B$9+Assumptions!$B$29)/1000000+Assumptions!$B$34*(Assumptions!$B$30*1000*((Assumptions!$B$15*Assumptions!$B$16*($A26*Assumptions!$B$6)+Assumptions!$B$15*(1-Assumptions!$B$16)*($A26*Assumptions!$B$6)*Assumptions!$B$8+(1-Assumptions!$B$15)*6*Assumptions!$B$7)*(1-Assumptions!$B$19)-Assumptions!$B$17-Assumptions!$B$18)*Assumptions!$B$31/1000000-Assumptions!$B$32)*Assumptions!$B$36*(1-(1+Assumptions!$B$9)^-Assumptions!$B$35)/Assumptions!$B$9+(((Assumptions!$B$39*365*((Assumptions!$C$15*Assumptions!$C$16*($A26*Assumptions!$B$6)+Assumptions!$C$15*(1-Assumptions!$C$16)*($A26*Assumptions!$B$6)*Assumptions!$B$8+(1-Assumptions!$C$15)*6*Assumptions!$B$7)*(1-Assumptions!$C$19)-Assumptions!$C$17-Assumptions!$C$18)*(1-Assumptions!$B$45)/1000000)*(1-(1+Assumptions!$B$9)^-Assumptions!$B$40)/Assumptions!$B$9+(Assumptions!$B$39*365*((Assumptions!$C$15*Assumptions!$C$16*($A26*Assumptions!$B$6)+Assumptions!$C$15*(1-Assumptions!$C$16)*($A26*Assumptions!$B$6)*Assumptions!$B$8+(1-Assumptions!$C$15)*6*Assumptions!$B$7)*(1-Assumptions!$C$19)-Assumptions!$C$17-Assumptions!$C$18)*(1-Assumptions!$B$45)/1000000)/(Assumptions!$B$9+Assumptions!$B$41)*(1+Assumptions!$B$9)^-Assumptions!$B$40)/(1+Assumptions!$B$9)^(Assumptions!$B$43+Assumptions!$B$44/2)-Assumptions!$B$42/(1+Assumptions!$B$9)^(Assumptions!$B$43/2))*F$24+Assumptions!$B$49*365*((Assumptions!$D$15*Assumptions!$D$16*($A26*Assumptions!$B$6)+Assumptions!$D$15*(1-Assumptions!$D$16)*($A26*Assumptions!$B$6)*Assumptions!$B$8+(1-Assumptions!$D$15)*6*Assumptions!$B$7)*(1-Assumptions!$D$19)-Assumptions!$D$17-Assumptions!$D$18)*(1-Assumptions!$B$51)/(Assumptions!$B$9+Assumptions!$B$50)/1000000+Assumptions!$B$52*1000*Assumptions!$B$53/1000000-Assumptions!$B$56/Assumptions!$B$9-Assumptions!$B$59)*(1-Assumptions!$B$60)+Assumptions!$B$57+Assumptions!$B$58)/Assumptions!$B$10 -> 25.266626
A27: 75 | B27: =((Assumptions!$B$28*365*((Assumptions!$B$15*Assumptions!$B$16*($A27*Assumptions!$B$6)+Assumptions!$B$15*(1-Assumptions!$B$16)*($A27*Assumptions!$B$6)*Assumptions!$B$8+(1-Assumptions!$B$15)*6*Assumptions!$B$7)*(1-Assumptions!$B$19)-Assumptions!$B$17-Assumptions!$B$18)/(Assumptions!$B$9+Assumptions!$B$29)/1000000+Assumptions!$B$34*(Assumptions!$B$30*1000*((Assumptions!$B$15*Assumptions!$B$16*($A27*Assumptions!$B$6)+Assumptions!$B$15*(1-Assumptions!$B$16)*($A27*Assumptions!$B$6)*Assumptions!$B$8+(1-Assumptions!$B$15)*6*Assumptions!$B$7)*(1-Assumptions!$B$19)-Assumptions!$B$17-Assumptions!$B$18)*Assumptions!$B$31/1000000-Assumptions!$B$32)*Assumptions!$B$36*(1-(1+Assumptions!$B$9)^-Assumptions!$B$35)/Assumptions!$B$9+(((Assumptions!$B$39*365*((Assumptions!$C$15*Assumptions!$C$16*($A27*Assumptions!$B$6)+Assumptions!$C$15*(1-Assumptions!$C$16)*($A27*Assumptions!$B$6)*Assumptions!$B$8+(1-Assumptions!$C$15)*6*Assumptions!$B$7)*(1-Assumptions!$C$19)-Assumptions!$C$17-Assumptions!$C$18)*(1-Assumptions!$B$45)/1000000)*(1-(1+Assumptions!$B$9)^-Assumptions!$B$40)/Assumptions!$B$9+(Assumptions!$B$39*365*((Assumptions!$C$15*Assumptions!$C$16*($A27*Assumptions!$B$6)+Assumptions!$C$15*(1-Assumptions!$C$16)*($A27*Assumptions!$B$6)*Assumptions!$B$8+(1-Assumptions!$C$15)*6*Assumptions!$B$7)*(1-Assumptions!$C$19)-Assumptions!$C$17-Assumptions!$C$18)*(1-Assumptions!$B$45)/1000000)/(Assumptions!$B$9+Assumptions!$B$41)*(1+Assumptions!$B$9)^-Assumptions!$B$40)/(1+Assumptions!$B$9)^(Assumptions!$B$43+Assumptions!$B$44/2)-Assumptions!$B$42/(1+Assumptions!$B$9)^(Assumptions!$B$43/2))*B$24+Assumptions!$B$49*365*((Assumptions!$D$15*Assumptions!$D$16*($A27*Assumptions!$B$6)+Assumptions!$D$15*(1-Assumptions!$D$16)*($A27*Assumptions!$B$6)*Assumptions!$B$8+(1-Assumptions!$D$15)*6*Assumptions!$B$7)*(1-Assumptions!$D$19)-Assumptions!$D$17-Assumptions!$D$18)*(1-Assumptions!$B$51)/(Assumptions!$B$9+Assumptions!$B$50)/1000000+Assumptions!$B$52*1000*Assumptions!$B$53/1000000-Assumptions!$B$56/Assumptions!$B$9-Assumptions!$B$59)*(1-Assumptions!$B$60)+Assumptions!$B$57+Assumptions!$B$58)/Assumptions!$B$10 -> 27.796488 | C27: =((Assumptions!$B$28*365*((Assumptions!$B$15*Assumptions!$B$16*($A27*Assumptions!$B$6)+Assumptions!$B$15*(1-Assumptions!$B$16)*($A27*Assumptions!$B$6)*Assumptions!$B$8+(1-Assumptions!$B$15)*6*Assumptions!$B$7)*(1-Assumptions!$B$19)-Assumptions!$B$17-Assumptions!$B$18)/(Assumptions!$B$9+Assumptions!$B$29)/1000000+Assumptions!$B$34*(Assumptions!$B$30*1000*((Assumptions!$B$15*Assumptions!$B$16*($A27*Assumptions!$B$6)+Assumptions!$B$15*(1-Assumptions!$B$16)*($A27*Assumptions!$B$6)*Assumptions!$B$8+(1-Assumptions!$B$15)*6*Assumptions!$B$7)*(1-Assumptions!$B$19)-Assumptions!$B$17-Assumptions!$B$18)*Assumptions!$B$31/1000000-Assumptions!$B$32)*Assumptions!$B$36*(1-(1+Assumptions!$B$9)^-Assumptions!$B$35)/Assumptions!$B$9+(((Assumptions!$B$39*365*((Assumptions!$C$15*Assumptions!$C$16*($A27*Assumptions!$B$6)+Assumptions!$C$15*(1-Assumptions!$C$16)*($A27*Assumptions!$B$6)*Assumptions!$B$8+(1-Assumptions!$C$15)*6*Assumptions!$B$7)*(1-Assumptions!$C$19)-Assumptions!$C$17-Assumptions!$C$18)*(1-Assumptions!$B$45)/1000000)*(1-(1+Assumptions!$B$9)^-Assumptions!$B$40)/Assumptions!$B$9+(Assumptions!$B$39*365*((Assumptions!$C$15*Assumptions!$C$16*($A27*Assumptions!$B$6)+Assumptions!$C$15*(1-Assumptions!$C$16)*($A27*Assumptions!$B$6)*Assumptions!$B$8+(1-Assumptions!$C$15)*6*Assumptions!$B$7)*(1-Assumptions!$C$19)-Assumptions!$C$17-Assumptions!$C$18)*(1-Assumptions!$B$45)/1000000)/(Assumptions!$B$9+Assumptions!$B$41)*(1+Assumptions!$B$9)^-Assumptions!$B$40)/(1+Assumptions!$B$9)^(Assumptions!$B$43+Assumptions!$B$44/2)-Assumptions!$B$42/(1+Assumptions!$B$9)^(Assumptions!$B$43/2))*C$24+Assumptions!$B$49*365*((Assumptions!$D$15*Assumptions!$D$16*($A27*Assumptions!$B$6)+Assumptions!$D$15*(1-Assumptions!$D$16)*($A27*Assumptions!$B$6)*Assumptions!$B$8+(1-Assumptions!$D$15)*6*Assumptions!$B$7)*(1-Assumptions!$D$19)-Assumptions!$D$17-Assumptions!$D$18)*(1-Assumptions!$B$51)/(Assumptions!$B$9+Assumptions!$B$50)/1000000+Assumptions!$B$52*1000*Assumptions!$B$53/1000000-Assumptions!$B$56/Assumptions!$B$9-Assumptions!$B$59)*(1-Assumptions!$B$60)+Assumptions!$B$57+Assumptions!$B$58)/Assumptions!$B$10 -> 28.456645 | D27: =((Assumptions!$B$28*365*((Assumptions!$B$15*Assumptions!$B$16*($A27*Assumptions!$B$6)+Assumptions!$B$15*(1-Assumptions!$B$16)*($A27*Assumptions!$B$6)*Assumptions!$B$8+(1-Assumptions!$B$15)*6*Assumptions!$B$7)*(1-Assumptions!$B$19)-Assumptions!$B$17-Assumptions!$B$18)/(Assumptions!$B$9+Assumptions!$B$29)/1000000+Assumptions!$B$34*(Assumptions!$B$30*1000*((Assumptions!$B$15*Assumptions!$B$16*($A27*Assumptions!$B$6)+Assumptions!$B$15*(1-Assumptions!$B$16)*($A27*Assumptions!$B$6)*Assumptions!$B$8+(1-Assumptions!$B$15)*6*Assumptions!$B$7)*(1-Assumptions!$B$19)-Assumptions!$B$17-Assumptions!$B$18)*Assumptions!$B$31/1000000-Assumptions!$B$32)*Assumptions!$B$36*(1-(1+Assumptions!$B$9)^-Assumptions!$B$35)/Assumptions!$B$9+(((Assumptions!$B$39*365*((Assumptions!$C$15*Assumptions!$C$16*($A27*Assumptions!$B$6)+Assumptions!$C$15*(1-Assumptions!$C$16)*($A27*Assumptions!$B$6)*Assumptions!$B$8+(1-Assumptions!$C$15)*6*Assumptions!$B$7)*(1-Assumptions!$C$19)-Assumptions!$C$17-Assumptions!$C$18)*(1-Assumptions!$B$45)/1000000)*(1-(1+Assumptions!$B$9)^-Assumptions!$B$40)/Assumptions!$B$9+(Assumptions!$B$39*365*((Assumptions!$C$15*Assumptions!$C$16*($A27*Assumptions!$B$6)+Assumptions!$C$15*(1-Assumptions!$C$16)*($A27*Assumptions!$B$6)*Assumptions!$B$8+(1-Assumptions!$C$15)*6*Assumptions!$B$7)*(1-Assumptions!$C$19)-Assumptions!$C$17-Assumptions!$C$18)*(1-Assumptions!$B$45)/1000000)/(Assumptions!$B$9+Assumptions!$B$41)*(1+Assumptions!$B$9)^-Assumptions!$B$40)/(1+Assumptions!$B$9)^(Assumptions!$B$43+Assumptions!$B$44/2)-Assumptions!$B$42/(1+Assumptions!$B$9)^(Assumptions!$B$43/2))*D$24+Assumptions!$B$49*365*((Assumptions!$D$15*Assumptions!$D$16*($A27*Assumptions!$B$6)+Assumptions!$D$15*(1-Assumptions!$D$16)*($A27*Assumptions!$B$6)*Assumptions!$B$8+(1-Assumptions!$D$15)*6*Assumptions!$B$7)*(1-Assumptions!$D$19)-Assumptions!$D$17-Assumptions!$D$18)*(1-Assumptions!$B$51)/(Assumptions!$B$9+Assumptions!$B$50)/1000000+Assumptions!$B$52*1000*Assumptions!$B$53/1000000-Assumptions!$B$56/Assumptions!$B$9-Assumptions!$B$59)*(1-Assumptions!$B$60)+Assumptions!$B$57+Assumptions!$B$58)/Assumptions!$B$10 -> 29.116802 | E27: =((Assumptions!$B$28*365*((Assumptions!$B$15*Assumptions!$B$16*($A27*Assumptions!$B$6)+Assumptions!$B$15*(1-Assumptions!$B$16)*($A27*Assumptions!$B$6)*Assumptions!$B$8+(1-Assumptions!$B$15)*6*Assumptions!$B$7)*(1-Assumptions!$B$19)-Assumptions!$B$17-Assumptions!$B$18)/(Assumptions!$B$9+Assumptions!$B$29)/1000000+Assumptions!$B$34*(Assumptions!$B$30*1000*((Assumptions!$B$15*Assumptions!$B$16*($A27*Assumptions!$B$6)+Assumptions!$B$15*(1-Assumptions!$B$16)*($A27*Assumptions!$B$6)*Assumptions!$B$8+(1-Assumptions!$B$15)*6*Assumptions!$B$7)*(1-Assumptions!$B$19)-Assumptions!$B$17-Assumptions!$B$18)*Assumptions!$B$31/1000000-Assumptions!$B$32)*Assumptions!$B$36*(1-(1+Assumptions!$B$9)^-Assumptions!$B$35)/Assumptions!$B$9+(((Assumptions!$B$39*365*((Assumptions!$C$15*Assumptions!$C$16*($A27*Assumptions!$B$6)+Assumptions!$C$15*(1-Assumptions!$C$16)*($A27*Assumptions!$B$6)*Assumptions!$B$8+(1-Assumptions!$C$15)*6*Assumptions!$B$7)*(1-Assumptions!$C$19)-Assumptions!$C$17-Assumptions!$C$18)*(1-Assumptions!$B$45)/1000000)*(1-(1+Assumptions!$B$9)^-Assumptions!$B$40)/Assumptions!$B$9+(Assumptions!$B$39*365*((Assumptions!$C$15*Assumptions!$C$16*($A27*Assumptions!$B$6)+Assumptions!$C$15*(1-Assumptions!$C$16)*($A27*Assumptions!$B$6)*Assumptions!$B$8+(1-Assumptions!$C$15)*6*Assumptions!$B$7)*(1-Assumptions!$C$19)-Assumptions!$C$17-Assumptions!$C$18)*(1-Assumptions!$B$45)/1000000)/(Assumptions!$B$9+Assumptions!$B$41)*(1+Assumptions!$B$9)^-Assumptions!$B$40)/(1+Assumptions!$B$9)^(Assumptions!$B$43+Assumptions!$B$44/2)-Assumptions!$B$42/(1+Assumptions!$B$9)^(Assumptions!$B$43/2))*E$24+Assumptions!$B$49*365*((Assumptions!$D$15*Assumptions!$D$16*($A27*Assumptions!$B$6)+Assumptions!$D$15*(1-Assumptions!$D$16)*($A27*Assumptions!$B$6)*Assumptions!$B$8+(1-Assumptions!$D$15)*6*Assumptions!$B$7)*(1-Assumptions!$D$19)-Assumptions!$D$17-Assumptions!$D$18)*(1-Assumptions!$B$51)/(Assumptions!$B$9+Assumptions!$B$50)/1000000+Assumptions!$B$52*1000*Assumptions!$B$53/1000000-Assumptions!$B$56/Assumptions!$B$9-Assumptions!$B$59)*(1-Assumptions!$B$60)+Assumptions!$B$57+Assumptions!$B$58)/Assumptions!$B$10 -> 29.776959 | F27: =((Assumptions!$B$28*365*((Assumptions!$B$15*Assumptions!$B$16*($A27*Assumptions!$B$6)+Assumptions!$B$15*(1-Assumptions!$B$16)*($A27*Assumptions!$B$6)*Assumptions!$B$8+(1-Assumptions!$B$15)*6*Assumptions!$B$7)*(1-Assumptions!$B$19)-Assumptions!$B$17-Assumptions!$B$18)/(Assumptions!$B$9+Assumptions!$B$29)/1000000+Assumptions!$B$34*(Assumptions!$B$30*1000*((Assumptions!$B$15*Assumptions!$B$16*($A27*Assumptions!$B$6)+Assumptions!$B$15*(1-Assumptions!$B$16)*($A27*Assumptions!$B$6)*Assumptions!$B$8+(1-Assumptions!$B$15)*6*Assumptions!$B$7)*(1-Assumptions!$B$19)-Assumptions!$B$17-Assumptions!$B$18)*Assumptions!$B$31/1000000-Assumptions!$B$32)*Assumptions!$B$36*(1-(1+Assumptions!$B$9)^-Assumptions!$B$35)/Assumptions!$B$9+(((Assumptions!$B$39*365*((Assumptions!$C$15*Assumptions!$C$16*($A27*Assumptions!$B$6)+Assumptions!$C$15*(1-Assumptions!$C$16)*($A27*Assumptions!$B$6)*Assumptions!$B$8+(1-Assumptions!$C$15)*6*Assumptions!$B$7)*(1-Assumptions!$C$19)-Assumptions!$C$17-Assumptions!$C$18)*(1-Assumptions!$B$45)/1000000)*(1-(1+Assumptions!$B$9)^-Assumptions!$B$40)/Assumptions!$B$9+(Assumptions!$B$39*365*((Assumptions!$C$15*Assumptions!$C$16*($A27*Assumptions!$B$6)+Assumptions!$C$15*(1-Assumptions!$C$16)*($A27*Assumptions!$B$6)*Assumptions!$B$8+(1-Assumptions!$C$15)*6*Assumptions!$B$7)*(1-Assumptions!$C$19)-Assumptions!$C$17-Assumptions!$C$18)*(1-Assumptions!$B$45)/1000000)/(Assumptions!$B$9+Assumptions!$B$41)*(1+Assumptions!$B$9)^-Assumptions!$B$40)/(1+Assumptions!$B$9)^(Assumptions!$B$43+Assumptions!$B$44/2)-Assumptions!$B$42/(1+Assumptions!$B$9)^(Assumptions!$B$43/2))*F$24+Assumptions!$B$49*365*((Assumptions!$D$15*Assumptions!$D$16*($A27*Assumptions!$B$6)+Assumptions!$D$15*(1-Assumptions!$D$16)*($A27*Assumptions!$B$6)*Assumptions!$B$8+(1-Assumptions!$D$15)*6*Assumptions!$B$7)*(1-Assumptions!$D$19)-Assumptions!$D$17-Assumptions!$D$18)*(1-Assumptions!$B$51)/(Assumptions!$B$9+Assumptions!$B$50)/1000000+Assumptions!$B$52*1000*Assumptions!$B$53/1000000-Assumptions!$B$56/Assumptions!$B$9-Assumptions!$B$59)*(1-Assumptions!$B$60)+Assumptions!$B$57+Assumptions!$B$58)/Assumptions!$B$10 -> 30.437116
A28: 85 | B28: =((Assumptions!$B$28*365*((Assumptions!$B$15*Assumptions!$B$16*($A28*Assumptions!$B$6)+Assumptions!$B$15*(1-Assumptions!$B$16)*($A28*Assumptions!$B$6)*Assumptions!$B$8+(1-Assumptions!$B$15)*6*Assumptions!$B$7)*(1-Assumptions!$B$19)-Assumptions!$B$17-Assumptions!$B$18)/(Assumptions!$B$9+Assumptions!$B$29)/1000000+Assumptions!$B$34*(Assumptions!$B$30*1000*((Assumptions!$B$15*Assumptions!$B$16*($A28*Assumptions!$B$6)+Assumptions!$B$15*(1-Assumptions!$B$16)*($A28*Assumptions!$B$6)*Assumptions!$B$8+(1-Assumptions!$B$15)*6*Assumptions!$B$7)*(1-Assumptions!$B$19)-Assumptions!$B$17-Assumptions!$B$18)*Assumptions!$B$31/1000000-Assumptions!$B$32)*Assumptions!$B$36*(1-(1+Assumptions!$B$9)^-Assumptions!$B$35)/Assumptions!$B$9+(((Assumptions!$B$39*365*((Assumptions!$C$15*Assumptions!$C$16*($A28*Assumptions!$B$6)+Assumptions!$C$15*(1-Assumptions!$C$16)*($A28*Assumptions!$B$6)*Assumptions!$B$8+(1-Assumptions!$C$15)*6*Assumptions!$B$7)*(1-Assumptions!$C$19)-Assumptions!$C$17-Assumptions!$C$18)*(1-Assumptions!$B$45)/1000000)*(1-(1+Assumptions!$B$9)^-Assumptions!$B$40)/Assumptions!$B$9+(Assumptions!$B$39*365*((Assumptions!$C$15*Assumptions!$C$16*($A28*Assumptions!$B$6)+Assumptions!$C$15*(1-Assumptions!$C$16)*($A28*Assumptions!$B$6)*Assumptions!$B$8+(1-Assumptions!$C$15)*6*Assumptions!$B$7)*(1-Assumptions!$C$19)-Assumptions!$C$17-Assumptions!$C$18)*(1-Assumptions!$B$45)/1000000)/(Assumptions!$B$9+Assumptions!$B$41)*(1+Assumptions!$B$9)^-Assumptions!$B$40)/(1+Assumptions!$B$9)^(Assumptions!$B$43+Assumptions!$B$44/2)-Assumptions!$B$42/(1+Assumptions!$B$9)^(Assumptions!$B$43/2))*B$24+Assumptions!$B$49*365*((Assumptions!$D$15*Assumptions!$D$16*($A28*Assumptions!$B$6)+Assumptions!$D$15*(1-Assumptions!$D$16)*($A28*Assumptions!$B$6)*Assumptions!$B$8+(1-Assumptions!$D$15)*6*Assumptions!$B$7)*(1-Assumptions!$D$19)-Assumptions!$D$17-Assumptions!$D$18)*(1-Assumptions!$B$51)/(Assumptions!$B$9+Assumptions!$B$50)/1000000+Assumptions!$B$52*1000*Assumptions!$B$53/1000000-Assumptions!$B$56/Assumptions!$B$9-Assumptions!$B$59)*(1-Assumptions!$B$60)+Assumptions!$B$57+Assumptions!$B$58)/Assumptions!$B$10 -> 32.746845 | C28: =((Assumptions!$B$28*365*((Assumptions!$B$15*Assumptions!$B$16*($A28*Assumptions!$B$6)+Assumptions!$B$15*(1-Assumptions!$B$16)*($A28*Assumptions!$B$6)*Assumptions!$B$8+(1-Assumptions!$B$15)*6*Assumptions!$B$7)*(1-Assumptions!$B$19)-Assumptions!$B$17-Assumptions!$B$18)/(Assumptions!$B$9+Assumptions!$B$29)/1000000+Assumptions!$B$34*(Assumptions!$B$30*1000*((Assumptions!$B$15*Assumptions!$B$16*($A28*Assumptions!$B$6)+Assumptions!$B$15*(1-Assumptions!$B$16)*($A28*Assumptions!$B$6)*Assumptions!$B$8+(1-Assumptions!$B$15)*6*Assumptions!$B$7)*(1-Assumptions!$B$19)-Assumptions!$B$17-Assumptions!$B$18)*Assumptions!$B$31/1000000-Assumptions!$B$32)*Assumptions!$B$36*(1-(1+Assumptions!$B$9)^-Assumptions!$B$35)/Assumptions!$B$9+(((Assumptions!$B$39*365*((Assumptions!$C$15*Assumptions!$C$16*($A28*Assumptions!$B$6)+Assumptions!$C$15*(1-Assumptions!$C$16)*($A28*Assumptions!$B$6)*Assumptions!$B$8+(1-Assumptions!$C$15)*6*Assumptions!$B$7)*(1-Assumptions!$C$19)-Assumptions!$C$17-Assumptions!$C$18)*(1-Assumptions!$B$45)/1000000)*(1-(1+Assumptions!$B$9)^-Assumptions!$B$40)/Assumptions!$B$9+(Assumptions!$B$39*365*((Assumptions!$C$15*Assumptions!$C$16*($A28*Assumptions!$B$6)+Assumptions!$C$15*(1-Assumptions!$C$16)*($A28*Assumptions!$B$6)*Assumptions!$B$8+(1-Assumptions!$C$15)*6*Assumptions!$B$7)*(1-Assumptions!$C$19)-Assumptions!$C$17-Assumptions!$C$18)*(1-Assumptions!$B$45)/1000000)/(Assumptions!$B$9+Assumptions!$B$41)*(1+Assumptions!$B$9)^-Assumptions!$B$40)/(1+Assumptions!$B$9)^(Assumptions!$B$43+Assumptions!$B$44/2)-Assumptions!$B$42/(1+Assumptions!$B$9)^(Assumptions!$B$43/2))*C$24+Assumptions!$B$49*365*((Assumptions!$D$15*Assumptions!$D$16*($A28*Assumptions!$B$6)+Assumptions!$D$15*(1-Assumptions!$D$16)*($A28*Assumptions!$B$6)*Assumptions!$B$8+(1-Assumptions!$D$15)*6*Assumptions!$B$7)*(1-Assumptions!$D$19)-Assumptions!$D$17-Assumptions!$D$18)*(1-Assumptions!$B$51)/(Assumptions!$B$9+Assumptions!$B$50)/1000000+Assumptions!$B$52*1000*Assumptions!$B$53/1000000-Assumptions!$B$56/Assumptions!$B$9-Assumptions!$B$59)*(1-Assumptions!$B$60)+Assumptions!$B$57+Assumptions!$B$58)/Assumptions!$B$10 -> 33.462035 | D28: =((Assumptions!$B$28*365*((Assumptions!$B$15*Assumptions!$B$16*($A28*Assumptions!$B$6)+Assumptions!$B$15*(1-Assumptions!$B$16)*($A28*Assumptions!$B$6)*Assumptions!$B$8+(1-Assumptions!$B$15)*6*Assumptions!$B$7)*(1-Assumptions!$B$19)-Assumptions!$B$17-Assumptions!$B$18)/(Assumptions!$B$9+Assumptions!$B$29)/1000000+Assumptions!$B$34*(Assumptions!$B$30*1000*((Assumptions!$B$15*Assumptions!$B$16*($A28*Assumptions!$B$6)+Assumptions!$B$15*(1-Assumptions!$B$16)*($A28*Assumptions!$B$6)*Assumptions!$B$8+(1-Assumptions!$B$15)*6*Assumptions!$B$7)*(1-Assumptions!$B$19)-Assumptions!$B$17-Assumptions!$B$18)*Assumptions!$B$31/1000000-Assumptions!$B$32)*Assumptions!$B$36*(1-(1+Assumptions!$B$9)^-Assumptions!$B$35)/Assumptions!$B$9+(((Assumptions!$B$39*365*((Assumptions!$C$15*Assumptions!$C$16*($A28*Assumptions!$B$6)+Assumptions!$C$15*(1-Assumptions!$C$16)*($A28*Assumptions!$B$6)*Assumptions!$B$8+(1-Assumptions!$C$15)*6*Assumptions!$B$7)*(1-Assumptions!$C$19)-Assumptions!$C$17-Assumptions!$C$18)*(1-Assumptions!$B$45)/1000000)*(1-(1+Assumptions!$B$9)^-Assumptions!$B$40)/Assumptions!$B$9+(Assumptions!$B$39*365*((Assumptions!$C$15*Assumptions!$C$16*($A28*Assumptions!$B$6)+Assumptions!$C$15*(1-Assumptions!$C$16)*($A28*Assumptions!$B$6)*Assumptions!$B$8+(1-Assumptions!$C$15)*6*Assumptions!$B$7)*(1-Assumptions!$C$19)-Assumptions!$C$17-Assumptions!$C$18)*(1-Assumptions!$B$45)/1000000)/(Assumptions!$B$9+Assumptions!$B$41)*(1+Assumptions!$B$9)^-Assumptions!$B$40)/(1+Assumptions!$B$9)^(Assumptions!$B$43+Assumptions!$B$44/2)-Assumptions!$B$42/(1+Assumptions!$B$9)^(Assumptions!$B$43/2))*D$24+Assumptions!$B$49*365*((Assumptions!$D$15*Assumptions!$D$16*($A28*Assumptions!$B$6)+Assumptions!$D$15*(1-Assumptions!$D$16)*($A28*Assumptions!$B$6)*Assumptions!$B$8+(1-Assumptions!$D$15)*6*Assumptions!$B$7)*(1-Assumptions!$D$19)-Assumptions!$D$17-Assumptions!$D$18)*(1-Assumptions!$B$51)/(Assumptions!$B$9+Assumptions!$B$50)/1000000+Assumptions!$B$52*1000*Assumptions!$B$53/1000000-Assumptions!$B$56/Assumptions!$B$9-Assumptions!$B$59)*(1-Assumptions!$B$60)+Assumptions!$B$57+Assumptions!$B$58)/Assumptions!$B$10 -> 34.177225 | E28: =((Assumptions!$B$28*365*((Assumptions!$B$15*Assumptions!$B$16*($A28*Assumptions!$B$6)+Assumptions!$B$15*(1-Assumptions!$B$16)*($A28*Assumptions!$B$6)*Assumptions!$B$8+(1-Assumptions!$B$15)*6*Assumptions!$B$7)*(1-Assumptions!$B$19)-Assumptions!$B$17-Assumptions!$B$18)/(Assumptions!$B$9+Assumptions!$B$29)/1000000+Assumptions!$B$34*(Assumptions!$B$30*1000*((Assumptions!$B$15*Assumptions!$B$16*($A28*Assumptions!$B$6)+Assumptions!$B$15*(1-Assumptions!$B$16)*($A28*Assumptions!$B$6)*Assumptions!$B$8+(1-Assumptions!$B$15)*6*Assumptions!$B$7)*(1-Assumptions!$B$19)-Assumptions!$B$17-Assumptions!$B$18)*Assumptions!$B$31/1000000-Assumptions!$B$32)*Assumptions!$B$36*(1-(1+Assumptions!$B$9)^-Assumptions!$B$35)/Assumptions!$B$9+(((Assumptions!$B$39*365*((Assumptions!$C$15*Assumptions!$C$16*($A28*Assumptions!$B$6)+Assumptions!$C$15*(1-Assumptions!$C$16)*($A28*Assumptions!$B$6)*Assumptions!$B$8+(1-Assumptions!$C$15)*6*Assumptions!$B$7)*(1-Assumptions!$C$19)-Assumptions!$C$17-Assumptions!$C$18)*(1-Assumptions!$B$45)/1000000)*(1-(1+Assumptions!$B$9)^-Assumptions!$B$40)/Assumptions!$B$9+(Assumptions!$B$39*365*((Assumptions!$C$15*Assumptions!$C$16*($A28*Assumptions!$B$6)+Assumptions!$C$15*(1-Assumptions!$C$16)*($A28*Assumptions!$B$6)*Assumptions!$B$8+(1-Assumptions!$C$15)*6*Assumptions!$B$7)*(1-Assumptions!$C$19)-Assumptions!$C$17-Assumptions!$C$18)*(1-Assumptions!$B$45)/1000000)/(Assumptions!$B$9+Assumptions!$B$41)*(1+Assumptions!$B$9)^-Assumptions!$B$40)/(1+Assumptions!$B$9)^(Assumptions!$B$43+Assumptions!$B$44/2)-Assumptions!$B$42/(1+Assumptions!$B$9)^(Assumptions!$B$43/2))*E$24+Assumptions!$B$49*365*((Assumptions!$D$15*Assumptions!$D$16*($A28*Assumptions!$B$6)+Assumptions!$D$15*(1-Assumptions!$D$16)*($A28*Assumptions!$B$6)*Assumptions!$B$8+(1-Assumptions!$D$15)*6*Assumptions!$B$7)*(1-Assumptions!$D$19)-Assumptions!$D$17-Assumptions!$D$18)*(1-Assumptions!$B$51)/(Assumptions!$B$9+Assumptions!$B$50)/1000000+Assumptions!$B$52*1000*Assumptions!$B$53/1000000-Assumptions!$B$56/Assumptions!$B$9-Assumptions!$B$59)*(1-Assumptions!$B$60)+Assumptions!$B$57+Assumptions!$B$58)/Assumptions!$B$10 -> 34.892415 | F28: =((Assumptions!$B$28*365*((Assumptions!$B$15*Assumptions!$B$16*($A28*Assumptions!$B$6)+Assumptions!$B$15*(1-Assumptions!$B$16)*($A28*Assumptions!$B$6)*Assumptions!$B$8+(1-Assumptions!$B$15)*6*Assumptions!$B$7)*(1-Assumptions!$B$19)-Assumptions!$B$17-Assumptions!$B$18)/(Assumptions!$B$9+Assumptions!$B$29)/1000000+Assumptions!$B$34*(Assumptions!$B$30*1000*((Assumptions!$B$15*Assumptions!$B$16*($A28*Assumptions!$B$6)+Assumptions!$B$15*(1-Assumptions!$B$16)*($A28*Assumptions!$B$6)*Assumptions!$B$8+(1-Assumptions!$B$15)*6*Assumptions!$B$7)*(1-Assumptions!$B$19)-Assumptions!$B$17-Assumptions!$B$18)*Assumptions!$B$31/1000000-Assumptions!$B$32)*Assumptions!$B$36*(1-(1+Assumptions!$B$9)^-Assumptions!$B$35)/Assumptions!$B$9+(((Assumptions!$B$39*365*((Assumptions!$C$15*Assumptions!$C$16*($A28*Assumptions!$B$6)+Assumptions!$C$15*(1-Assumptions!$C$16)*($A28*Assumptions!$B$6)*Assumptions!$B$8+(1-Assumptions!$C$15)*6*Assumptions!$B$7)*(1-Assumptions!$C$19)-Assumptions!$C$17-Assumptions!$C$18)*(1-Assumptions!$B$45)/1000000)*(1-(1+Assumptions!$B$9)^-Assumptions!$B$40)/Assumptions!$B$9+(Assumptions!$B$39*365*((Assumptions!$C$15*Assumptions!$C$16*($A28*Assumptions!$B$6)+Assumptions!$C$15*(1-Assumptions!$C$16)*($A28*Assumptions!$B$6)*Assumptions!$B$8+(1-Assumptions!$C$15)*6*Assumptions!$B$7)*(1-Assumptions!$C$19)-Assumptions!$C$17-Assumptions!$C$18)*(1-Assumptions!$B$45)/1000000)/(Assumptions!$B$9+Assumptions!$B$41)*(1+Assumptions!$B$9)^-Assumptions!$B$40)/(1+Assumptions!$B$9)^(Assumptions!$B$43+Assumptions!$B$44/2)-Assumptions!$B$42/(1+Assumptions!$B$9)^(Assumptions!$B$43/2))*F$24+Assumptions!$B$49*365*((Assumptions!$D$15*Assumptions!$D$16*($A28*Assumptions!$B$6)+Assumptions!$D$15*(1-Assumptions!$D$16)*($A28*Assumptions!$B$6)*Assumptions!$B$8+(1-Assumptions!$D$15)*6*Assumptions!$B$7)*(1-Assumptions!$D$19)-Assumptions!$D$17-Assumptions!$D$18)*(1-Assumptions!$B$51)/(Assumptions!$B$9+Assumptions!$B$50)/1000000+Assumptions!$B$52*1000*Assumptions!$B$53/1000000-Assumptions!$B$56/Assumptions!$B$9-Assumptions!$B$59)*(1-Assumptions!$B$60)+Assumptions!$B$57+Assumptions!$B$58)/Assumptions!$B$10 -> 35.607605
